Workbook

Sheet Yearly
A1: Year | B1: Nifty 50 | C1: Nifty PE | D1: Nifty PB | E1: 10yr Yeild | F1: Buffett Indicator | G1: Earning Yeild | H1: BEER ratio | I1: Percentile | M1: Valuation Score | N1: Nifty | O1: Nifty aft 5yr | P1: Future 5yr CAGR
I2: PE | J2: PB | K2: BEER | L2: Buffett
A3: 2000 | B3: 1263.55 | C3: 19.2 | D3: 4.14 | E3: 0.1088 | F3: 48.17475 | G3: =(1/C3) -> 0.052083333 | H3: =G3/E3 -> 0.47870711 | I3: =_xlfn.PERCENTRANK.INC($C$3:$C$28,C3) -> 0.32 | J3: =_xlfn.PERCENTRANK.INC($D$3:$D$28,D3) -> 0.8 | K3: =_xlfn.PERCENTRANK.INC($H$3:$H$28,H3) -> 0.08 | L3: =_xlfn.PERCENTRANK.INC($F$3:$F$28,F3) -> 0.08 | M3: =(I3*0.4)+(J3*0.2)+(K3*0.2)+((1-L3)*0.2) -> 0.488 | N3: 1263.55 | O3: 2836.55 | P3: =(O3/N3)^(1/5)-1 -> 0.17554593
A4: 2001 | B4: 1059.05 | C4: 15.35 | D4: 2.38 | E4: 0.07939 | F4: 30.646752 | G4: =(1/C4) -> 0.06514658 | H4: =G4/E4 -> 0.82058924 | I4: =_xlfn.PERCENTRANK.INC($C$3:$C$28,C4) -> 0.12 | J4: =_xlfn.PERCENTRANK.INC($D$3:$D$28,D4) -> 0 | K4: =_xlfn.PERCENTRANK.INC($H$3:$H$28,H4) -> 0.84 | L4: =_xlfn.PERCENTRANK.INC($F$3:$F$28,F4) -> 0 | M4: =(I4*0.4)+(J4*0.2)+(K4*0.2)+((1-L4)*0.2) -> 0.416 | N4: 1059.05 | O4: 3966.4 | P4: =(O4/N4)^(1/5)-1 -> 0.30225493
A5: 2002 | B5: 1093.5 | C5: 14.83 | D5: 2.39 | E5: 0.06083 | F5: 33.438061 | G5: =(1/C5) -> 0.067430883 | H5: =G5/E5 -> 1.1085136 | I5: =_xlfn.PERCENTRANK.INC($C$3:$C$28,C5) -> 0.04 | J5: =_xlfn.PERCENTRANK.INC($D$3:$D$28,D5) -> 0.04 | K5: =_xlfn.PERCENTRANK.INC($H$3:$H$28,H5) -> 0.96 | L5: =_xlfn.PERCENTRANK.INC($F$3:$F$28,F5) -> 0.04 | M5: =(I5*0.4)+(J5*0.2)+(K5*0.2)+((1-L5)*0.2) -> 0.408 | N5: 1093.5 | O5: 6138.6 | P5: =(O5/N5)^(1/5)-1 -> 0.41205011
A6: 2003 | B6: 1879.75 | C6: 20.73 | D6: 4.05 | E6: 0.05122 | F6: 50.846571 | G6: =(1/C6) -> 0.048239267 | H6: =G6/E6 -> 0.94180529 | I6: =_xlfn.PERCENTRANK.INC($C$3:$C$28,C6) -> 0.36 | J6: =_xlfn.PERCENTRANK.INC($D$3:$D$28,D6) -> 0.76 | K6: =_xlfn.PERCENTRANK.INC($H$3:$H$28,H6) -> 0.88 | L6: =_xlfn.PERCENTRANK.INC($F$3:$F$28,F6) -> 0.12 | M6: =(I6*0.4)+(J6*0.2)+(K6*0.2)+((1-L6)*0.2) -> 0.648 | N6: 1879.75 | O6: 2959.15 | P6: =(O6/N6)^(1/5)-1 -> 0.09499813
A7: 2004 | B7: 2080.5 | C7: 15.32 | D7: 3.61 | E7: 0.06706 | F7: 58.597294 | G7: =(1/C7) -> 0.065274151 | H7: =G7/E7 -> 0.97336939 | I7: =_xlfn.PERCENTRANK.INC($C$3:$C$28,C7) -> 0.08 | J7: =_xlfn.PERCENTRANK.INC($D$3:$D$28,D7) -> 0.52 | K7: =_xlfn.PERCENTRANK.INC($H$3:$H$28,H7) -> 0.92 | L7: =_xlfn.PERCENTRANK.INC($F$3:$F$28,F7) -> 0.16 | M7: =(I7*0.4)+(J7*0.2)+(K7*0.2)+((1-L7)*0.2) -> 0.488 | N7: 2080.5 | O7: 5201.05 | P7: =(O7/N7)^(1/5)-1 -> 0.2011152
A8: 2005 | B8: 2836.55 | C8: 17.16 | D8: 4.37 | E8: 0.0711 | F8: 76.152115 | G8: =(1/C8) -> 0.058275058 | H8: =G8/E8 -> 0.81962107 | I8: =_xlfn.PERCENTRANK.INC($C$3:$C$28,C8) -> 0.2 | J8: =_xlfn.PERCENTRANK.INC($D$3:$D$28,D8) -> 0.88 | K8: =_xlfn.PERCENTRANK.INC($H$3:$H$28,H8) -> 0.8 | L8: =_xlfn.PERCENTRANK.INC($F$3:$F$28,F8) -> 0.4 | M8: =(I8*0.4)+(J8*0.2)+(K8*0.2)+((1-L8)*0.2) -> 0.536 | N8: 2836.55 | O8: 6134.5 | P8: =(O8/N8)^(1/5)-1 -> 0.16680356
A9: 2006 | B9: 3966.4 | C9: 21.26 | D9: 5.07 | E9: 0.07619 | F9: 95.215152 | G9: =(1/C9) -> 0.047036689 | H9: =G9/E9 -> 0.6173604 | I9: =_xlfn.PERCENTRANK.INC($C$3:$C$28,C9) -> 0.44 | J9: =_xlfn.PERCENTRANK.INC($D$3:$D$28,D9) -> 0.96 | K9: =_xlfn.PERCENTRANK.INC($H$3:$H$28,H9) -> 0.48 | L9: =_xlfn.PERCENTRANK.INC($F$3:$F$28,F9) -> 0.56 | M9: =(I9*0.4)+(J9*0.2)+(K9*0.2)+((1-L9)*0.2) -> 0.552 | N9: 3966.4 | O9: 4624.3 | P9: =(O9/N9)^(1/5)-1 -> 0.031169119
A10: 2007 | B10: 6138.6 | C10: 27.62 | D10: 6.39 | E10: 0.07791 | F10: 161.23945 | G10: =(1/C10) -> 0.036205648 | H10: =G10/E10 -> 0.46471118 | I10: =_xlfn.PERCENTRANK.INC($C$3:$C$28,C10) -> 0.92 | J10: =_xlfn.PERCENTRANK.INC($D$3:$D$28,D10) -> 1 | K10: =_xlfn.PERCENTRANK.INC($H$3:$H$28,H10) -> 0.04 | L10: =_xlfn.PERCENTRANK.INC($F$3:$F$28,F10) -> 1 | M10: =(I10*0.4)+(J10*0.2)+(K10*0.2)+((1-L10)*0.2) -> 0.576 | N10: 6138.6 | O10: 5905.1 | P10: =(O10/N10)^(1/5)-1 -> -0.0077260631
A11: 2008 | B11: 2959.15 | C11: 12.97 | D11: 2.44 | E11: 0.0526 | F11: 66.003104 | G11: =(1/C11) -> 0.077101002 | H11: =G11/E11 -> 1.4657985 | I11: =_xlfn.PERCENTRANK.INC($C$3:$C$28,C11) -> 0 | J11: =_xlfn.PERCENTRANK.INC($D$3:$D$28,D11) -> 0.08 | K11: =_xlfn.PERCENTRANK.INC($H$3:$H$28,H11) -> 1 | L11: =_xlfn.PERCENTRANK.INC($F$3:$F$28,F11) -> 0.2 | M11: =(I11*0.4)+(J11*0.2)+(K11*0.2)+((1-L11)*0.2) -> 0.376 | N11: 2959.15 | O11: 6304 | P11: =(O11/N11)^(1/5)-1 -> 0.16329496
A12: 2009 | B12: 5201.05 | C12: 23.17 | D12: 3.65 | E12: 0.07679 | F12: 101.89449 | G12: =(1/C12) -> 0.043159258 | H12: =G12/E12 -> 0.56204268 | I12: =_xlfn.PERCENTRANK.INC($C$3:$C$28,C12) -> 0.68 | J12: =_xlfn.PERCENTRANK.INC($D$3:$D$28,D12) -> 0.56 | K12: =_xlfn.PERCENTRANK.INC($H$3:$H$28,H12) -> 0.28 | L12: =_xlfn.PERCENTRANK.INC($F$3:$F$28,F12) -> 0.72 | M12: =(I12*0.4)+(J12*0.2)+(K12*0.2)+((1-L12)*0.2) -> 0.496 | N12: 5201.05 | O12: 8282.7 | P12: =(O12/N12)^(1/5)-1 -> 0.097529445
A13: 2010 | B13: 6134.5 | C13: 24.48 | D13: 3.87 | E13: 0.07913 | F13: 105.18295 | G13: =(1/C13) -> 0.040849673 | H13: =G13/E13 -> 0.51623497 | I13: =_xlfn.PERCENTRANK.INC($C$3:$C$28,C13) -> 0.8 | J13: =_xlfn.PERCENTRANK.INC($D$3:$D$28,D13) -> 0.68 | K13: =_xlfn.PERCENTRANK.INC($H$3:$H$28,H13) -> 0.16 | L13: =_xlfn.PERCENTRANK.INC($F$3:$F$28,F13) -> 0.76 | M13: =(I13*0.4)+(J13*0.2)+(K13*0.2)+((1-L13)*0.2) -> 0.536 | N13: 6134.5 | O13: 7964.35 | P13: =(O13/N13)^(1/5)-1 -> 0.053596291
A14: 2011 | B14: 4624.3 | C14: 16.75 | D14: 2.76 | E14: 0.0856 | F14: 68.270064 | G14: =(1/C14) -> 0.059701493 | H14: =G14/E14 -> 0.69744734 | I14: =_xlfn.PERCENTRANK.INC($C$3:$C$28,C14) -> 0.16 | J14: =_xlfn.PERCENTRANK.INC($D$3:$D$28,D14) -> 0.12 | K14: =_xlfn.PERCENTRANK.INC($H$3:$H$28,H14) -> 0.72 | L14: =_xlfn.PERCENTRANK.INC($F$3:$F$28,F14) -> 0.28 | M14: =(I14*0.4)+(J14*0.2)+(K14*0.2)+((1-L14)*0.2) -> 0.376 | N14: 4624.3 | O14: 8185.8 | P14: =(O14/N14)^(1/5)-1 -> 0.12099332
... A23: 2020 | B23: 13981.75 | C23: 38.45 | D23: 3.96 | E23: 0.05894 | F23: 95.424502 | G23: =(1/C23) -> 0.026007802 | H23: =G23/E23 -> 0.44125895 | I23: =_xlfn.PERCENTRANK.INC($C$3:$C$28,C23) -> 1 | J23: =_xlfn.PERCENTRANK.INC($D$3:$D$28,D23) -> 0.72 | K23: =_xlfn.PERCENTRANK.INC($H$3:$H$28,H23) -> 0 | L23: =_xlfn.PERCENTRANK.INC($F$3:$F$28,F23) -> 0.6 | M23: =(I23*0.4)+(J23*0.2)+(K23*0.2)+((1-L23)*0.2) -> 0.624 | N23: 13981.75 | O23: 26129.6 | P23: =(O23/N23)^(1/5)-1 -> 0.13322004
A24: 2021 | B24: 17354.05 | C24: 24.11 | D24: 4.37 | E24: 0.06454 | F24: 112.02132 | G24: =(1/C24) -> 0.041476566 | H24: =G24/E24 -> 0.64264899 | I24: =_xlfn.PERCENTRANK.INC($C$3:$C$28,C24) -> 0.76 | J24: =_xlfn.PERCENTRANK.INC($D$3:$D$28,D24) -> 0.88 | K24: =_xlfn.PERCENTRANK.INC($H$3:$H$28,H24) -> 0.56 | L24: =_xlfn.PERCENTRANK.INC($F$3:$F$28,F24) -> 0.8 | M24: =(I24*0.4)+(J24*0.2)+(K24*0.2)+((1-L24)*0.2) -> 0.632 | N24: 17354.05
A25: 2022 | B25: 18105.3 | C25: 21.79 | D25: 4.25 | E25: 0.07327 | F25: 101.23306 | G25: =(1/C25) -> 0.045892611 | H25: =G25/E25 -> 0.62634927 | I25: =_xlfn.PERCENTRANK.INC($C$3:$C$28,C25) -> 0.52 | J25: =_xlfn.PERCENTRANK.INC($D$3:$D$28,D25) -> 0.84 | K25: =_xlfn.PERCENTRANK.INC($H$3:$H$28,H25) -> 0.52 | L25: =_xlfn.PERCENTRANK.INC($F$3:$F$28,F25) -> 0.68 | M25: =(I25*0.4)+(J25*0.2)+(K25*0.2)+((1-L25)*0.2) -> 0.544 | N25: 18105.3
A26: 2023 | B26: 21731.4 | C26: 23.17 | D26: 3.83 | E26: 0.07176 | F26: 119.28387 | G26: =(1/C26) -> 0.043159258 | H26: =G26/E26 -> 0.60143893 | I26: =_xlfn.PERCENTRANK.INC($C$3:$C$28,C26) -> 0.68 | J26: =_xlfn.PERCENTRANK.INC($D$3:$D$28,D26) -> 0.64 | K26: =_xlfn.PERCENTRANK.INC($H$3:$H$28,H26) -> 0.36 | L26: =_xlfn.PERCENTRANK.INC($F$3:$F$28,F26) -> 0.84 | M26: =(I26*0.4)+(J26*0.2)+(K26*0.2)+((1-L26)*0.2) -> 0.504 | N26: 21731.4
A27: 2024 | B27: 23644.8 | C27: 21.79 | D27: 3.53 | E27: 0.06759 | F27: 131.24143 | G27: =(1/C27) -> 0.045892611 | H27: =G27/E27 -> 0.67898522 | I27: =_xlfn.PERCENTRANK.INC($C$3:$C$28,C27) -> 0.52 | J27: =_xlfn.PERCENTRANK.INC($D$3:$D$28,D27) -> 0.4 | K27: =_xlfn.PERCENTRANK.INC($H$3:$H$28,H27) -> 0.68 | L27: =_xlfn.PERCENTRANK.INC($F$3:$F$28,F27) -> 0.88 | M27: =(I27*0.4)+(J27*0.2)+(K27*0.2)+((1-L27)*0.2) -> 0.448 | N27: 23644.8
A28: 2025 | B28: 26129.6 | C28: 22.75 | D28: 3.55 | E28: 0.06588 | F28: 137.7 | G28: =(1/C28) -> 0.043956044 | H28: =G28/E28 -> 0.66721378 | I28: =_xlfn.PERCENTRANK.INC($C$3:$C$28,C28) -> 0.64 | J28: =_xlfn.PERCENTRANK.INC($D$3:$D$28,D28) -> 0.44 | K28: =_xlfn.PERCENTRANK.INC($H$3:$H$28,H28) -> 0.64 | L28: =_xlfn.PERCENTRANK.INC($F$3:$F$28,F28) -> 0.92 | M28: =(I28*0.4)+(J28*0.2)+(K28*0.2)+((1-L28)*0.2) -> 0.488 | N28: 26129.6

Sheet Monthly
A1: Year | B1: Nifty 50 | C1: Nifty PE | D1: Nifty PB | E1: 10yr Yeild | F1: Buffett Indicator | G1: Earning Yeild | H1: BEER ratio | I1: Percentile | M1: Valuation Score | N1: Nifty | O1: Nifty aft 5yr | P1: Future 5yr CAGR
I2: PE | J2: PB | K2: BEER | L2: Buffett
A3: 37681 | B3: 978.2 | C3: 13.36 | D3: 2.15 | E3: 6.127 | F3: =(E3/'Yearly GDP'!$B$2)*100 -> 1189.8474 | G3: =1/C3 -> 0.074850299 | H3: =G3/E3*(100) -> 1.2216468 | I3: =_xlfn.PERCENTRANK.INC($C$3:$C$269,C3) -> 0.041 | J3: =_xlfn.PERCENTRANK.INC($D$3:$D$269,D3) -> 0.003 | K3: =_xlfn.PERCENTRANK.INC($H$3:$H$269,H3) -> 0.966 | L3: =_xlfn.PERCENTRANK.INC($F$3:$F$269,F3) -> 1 | M3: =(I3*0.4)+(J3*0.2)+(K3*0.2)+((1-L3)*0.2) -> 0.2102 | N3: 978.2 | O3: 4734.5 | P3: =(O3/N3)^(1/5)-1 -> 0.37078484
A4: 37712 | B4: 934.05 | C4: 13.14 | D4: 2.11 | E4: 5.882 | F4: =(E4/'Yearly GDP'!$B$2)*100 -> 1142.269 | G4: =1/C4 -> 0.076103501 | H4: =G4/E4*(100) -> 1.2938371 | I4: =_xlfn.PERCENTRANK.INC($C$3:$C$269,C4) -> 0.033 | J4: =_xlfn.PERCENTRANK.INC($D$3:$D$269,D4) -> 0 | K4: =_xlfn.PERCENTRANK.INC($H$3:$H$269,H4) -> 0.977 | L4: =_xlfn.PERCENTRANK.INC($F$3:$F$269,F4) -> 0.992 | M4: =(I4*0.4)+(J4*0.2)+(K4*0.2)+((1-L4)*0.2) -> 0.2102 | N4: 934.05 | O4: 5165.9 | P4: =(O4/N4)^(1/5)-1 -> 0.40784607
A5: 37742 | B5: 1006.8 | C5: 11.65 | D5: 2.17 | E5: 5.793 | F5: =(E5/'Yearly GDP'!$B$2)*100 -> 1124.9854 | G5: =1/C5 -> 0.08583691 | H5: =G5/E5*(100) -> 1.481735 | I5: =_xlfn.PERCENTRANK.INC($C$3:$C$269,C5) -> 0 | J5: =_xlfn.PERCENTRANK.INC($D$3:$D$269,D5) -> 0.007 | K5: =_xlfn.PERCENTRANK.INC($H$3:$H$269,H5) -> 0.996 | L5: =_xlfn.PERCENTRANK.INC($F$3:$F$269,F5) -> 0.984 | M5: =(I5*0.4)+(J5*0.2)+(K5*0.2)+((1-L5)*0.2) -> 0.2038 | N5: 1006.8 | O5: 4870.1 | P5: =(O5/N5)^(1/5)-1 -> 0.3706259
A6: 37773 | B6: 1134.15 | C6: 12.95 | D6: 2.44 | E6: 5.73 | F6: =(E6/'Yearly GDP'!$B$2)*100 -> 1112.751 | G6: =1/C6 -> 0.077220077 | H6: =G6/E6*(100) -> 1.3476453 | I6: =_xlfn.PERCENTRANK.INC($C$3:$C$269,C6) -> 0.022 | J6: =_xlfn.PERCENTRANK.INC($D$3:$D$269,D6) -> 0.026 | K6: =_xlfn.PERCENTRANK.INC($H$3:$H$269,H6) -> 0.981 | L6: =_xlfn.PERCENTRANK.INC($F$3:$F$269,F6) -> 0.981 | M6: =(I6*0.4)+(J6*0.2)+(K6*0.2)+((1-L6)*0.2) -> 0.214 | N6: 1134.15 | O6: 4040.55 | P6: =(O6/N6)^(1/5)-1 -> 0.28930004
A7: 37803 | B7: 1185.85 | C7: 12.84 | D7: 2.55 | E7: 5.616 | F7: =(E7/'Yearly GDP'!$B$2)*100 -> 1090.6125 | G7: =1/C7 -> 0.07788162 | H7: =G7/E7*(100) -> 1.386781 | I7: =_xlfn.PERCENTRANK.INC($C$3:$C$269,C7) -> 0.018 | J7: =_xlfn.PERCENTRANK.INC($D$3:$D$269,D7) -> 0.041 | K7: =_xlfn.PERCENTRANK.INC($H$3:$H$269,H7) -> 0.988 | L7: =_xlfn.PERCENTRANK.INC($F$3:$F$269,F7) -> 0.973 | M7: =(I7*0.4)+(J7*0.2)+(K7*0.2)+((1-L7)*0.2) -> 0.2184 | N7: 1185.85 | O7: 4332.95 | P7: =(O7/N7)^(1/5)-1 -> 0.29583822
A8: 37834 | B8: 1356.55 | C8: 14.95 | D8: 2.92 | E8: 5.282 | F8: =(E8/'Yearly GDP'!$B$2)*100 -> 1025.7506 | G8: =1/C8 -> 0.066889632 | H8: =G8/E8*(100) -> 1.2663694 | I8: =_xlfn.PERCENTRANK.INC($C$3:$C$269,C8) -> 0.093 | J8: =_xlfn.PERCENTRANK.INC($D$3:$D$269,D8) -> 0.097 | K8: =_xlfn.PERCENTRANK.INC($H$3:$H$269,H8) -> 0.973 | L8: =_xlfn.PERCENTRANK.INC($F$3:$F$269,F8) -> 0.966 | M8: =(I8*0.4)+(J8*0.2)+(K8*0.2)+((1-L8)*0.2) -> 0.258 | N8: 1356.55 | O8: 4360 | P8: =(O8/N8)^(1/5)-1 -> 0.26301974
A9: 37865 | B9: 1417.1 | C9: 15.61 | D9: 3.05 | E9: 5.174 | F9: =(E9/'Yearly GDP'!$B$2)*100 -> 1004.7773 | G9: =1/C9 -> 0.064061499 | H9: =G9/E9*(100) -> 1.2381426 | I9: =_xlfn.PERCENTRANK.INC($C$3:$C$269,C9) -> 0.105 | J9: =_xlfn.PERCENTRANK.INC($D$3:$D$269,D9) -> 0.172 | K9: =_xlfn.PERCENTRANK.INC($H$3:$H$269,H9) -> 0.969 | L9: =_xlfn.PERCENTRANK.INC($F$3:$F$269,F9) -> 0.954 | M9: =(I9*0.4)+(J9*0.2)+(K9*0.2)+((1-L9)*0.2) -> 0.2794 | N9: 1417.1 | O9: 3921.2 | P9: =(O9/N9)^(1/5)-1 -> 0.22575507
A10: 37895 | B10: 1555.9 | C10: 17.15 | D10: 3.35 | E10: 5.1 | F10: =(E10/'Yearly GDP'!$B$2)*100 -> 990.40665 | G10: =1/C10 -> 0.058309038 | H10: =G10/E10*(100) -> 1.1433145 | I10: =_xlfn.PERCENTRANK.INC($C$3:$C$269,C10) -> 0.15 | J10: =_xlfn.PERCENTRANK.INC($D$3:$D$269,D10) -> 0.296 | K10: =_xlfn.PERCENTRANK.INC($H$3:$H$269,H10) -> 0.943 | L10: =_xlfn.PERCENTRANK.INC($F$3:$F$269,F10) -> 0.913 | M10: =(I10*0.4)+(J10*0.2)+(K10*0.2)+((1-L10)*0.2) -> 0.3252 | N10: 1555.9 | O10: 2885.6 | P10: =(O10/N10)^(1/5)-1 -> 0.13149044
A11: 37926 | B11: 1615.25 | C11: 17.81 | D11: 3.47 | E11: 5.147 | F11: =(E11/'Yearly GDP'!$B$2)*100 -> 999.53393 | G11: =1/C11 -> 0.056148231 | H11: =G11/E11*(100) -> 1.0908924 | I11: =_xlfn.PERCENTRANK.INC($C$3:$C$269,C11) -> 0.199 | J11: =_xlfn.PERCENTRANK.INC($D$3:$D$269,D11) -> 0.398 | K11: =_xlfn.PERCENTRANK.INC($H$3:$H$269,H11) -> 0.936 | L11: =_xlfn.PERCENTRANK.INC($F$3:$F$269,F11) -> 0.928 | M11: =(I11*0.4)+(J11*0.2)+(K11*0.2)+((1-L11)*0.2) -> 0.3608 | N11: 1615.25 | O11: 2755.1 | P11: =(O11/N11)^(1/5)-1 -> 0.11270368
A12: 37956 | B12: 1879.75 | C12: 20.73 | D12: 4.05 | E12: 5.122 | F12: =(E12/'Yearly GDP'!$B$2)*100 -> 994.67899 | G12: =1/C12 -> 0.048239267 | H12: =G12/E12*(100) -> 0.94180529 | I12: =_xlfn.PERCENTRANK.INC($C$3:$C$269,C12) -> 0.428 | J12: =_xlfn.PERCENTRANK.INC($D$3:$D$269,D12) -> 0.763 | K12: =_xlfn.PERCENTRANK.INC($H$3:$H$269,H12) -> 0.868 | L12: =_xlfn.PERCENTRANK.INC($F$3:$F$269,F12) -> 0.921 | M12: =(I12*0.4)+(J12*0.2)+(K12*0.2)+((1-L12)*0.2) -> 0.5132 | N12: 1879.75 | O12: 2959.15 | P12: =(O12/N12)^(1/5)-1 -> 0.09499813
A13: 37987 | B13: 1809.75 | C13: 19.96 | D13: 3.9 | E13: 5.208 | F13: =(E13/'Yearly GDP'!$B$3)*100 -> 857.00181 | G13: =1/C13 -> 0.0501002 | H13: =G13/E13*(100) -> 0.96198541 | I13: =_xlfn.PERCENTRANK.INC($C$3:$C$269,C13) -> 0.342 | J13: =_xlfn.PERCENTRANK.INC($D$3:$D$269,D13) -> 0.714 | K13: =_xlfn.PERCENTRANK.INC($H$3:$H$269,H13) -> 0.875 | L13: =_xlfn.PERCENTRANK.INC($F$3:$F$269,F13) -> 0.827 | M13: =(I13*0.4)+(J13*0.2)+(K13*0.2)+((1-L13)*0.2) -> 0.4892 | N13: 1809.75 | O13: 2874.8 | P13: =(O13/N13)^(1/5)-1 -> 0.096977728
A14: 38018 | B14: 1800.3 | C14: 19.74 | D14: 3.89 | E14: 5.265 | F14: =(E14/'Yearly GDP'!$B$3)*100 -> 866.38144 | G14: =1/C14 -> 0.050658561 | H14: =G14/E14*(100) -> 0.9621759 | I14: =_xlfn.PERCENTRANK.INC($C$3:$C$269,C14) -> 0.327 | J14: =_xlfn.PERCENTRANK.INC($D$3:$D$269,D14) -> 0.706 | K14: =_xlfn.PERCENTRANK.INC($H$3:$H$269,H14) -> 0.879 | L14: =_xlfn.PERCENTRANK.INC($F$3:$F$269,F14) -> 0.834 | M14: =(I14*0.4)+(J14*0.2)+(K14*0.2)+((1-L14)*0.2) -> 0.481 | N14: 1800.3 | O14: 2763.65 | P14: =(O14/N14)^(1/5)-1 -> 0.089500997
A15: 38047 | B15: 1771.9 | C15: 20.7 | D15: 3.5 | E15: 5.147 | F15: =(E15/'Yearly GDP'!$B$3)*100 -> 846.96396 | G15: =1/C15 -> 0.048309179 | H15: =G15/E15*(100) -> 0.93858906 | I15: =_xlfn.PERCENTRANK.INC($C$3:$C$269,C15) -> 0.424 | J15: =_xlfn.PERCENTRANK.INC($D$3:$D$269,D15) -> 0.436 | K15: =_xlfn.PERCENTRANK.INC($H$3:$H$269,H15) -> 0.864 | L15: =_xlfn.PERCENTRANK.INC($F$3:$F$269,F15) -> 0.815 | M15: =(I15*0.4)+(J15*0.2)+(K15*0.2)+((1-L15)*0.2) -> 0.4666 | N15: 1771.9 | O15: 3020.95 | P15: =(O15/N15)^(1/5)-1 -> 0.11260464
A16: 38078 | B16: 1796.1 | C16: 18.68 | D16: 3.54 | E16: 5.117 | F16: =(E16/'Yearly GDP'!$B$3)*100 -> 842.02732 | G16: =1/C16 -> 0.053533191 | H16: =G16/E16*(100) -> 1.0461831 | I16: =_xlfn.PERCENTRANK.INC($C$3:$C$269,C16) -> 0.27 | J16: =_xlfn.PERCENTRANK.INC($D$3:$D$269,D16) -> 0.484 | K16: =_xlfn.PERCENTRANK.INC($H$3:$H$269,H16) -> 0.928 | L16: =_xlfn.PERCENTRANK.INC($F$3:$F$269,F16) -> 0.804 | M16: =(I16*0.4)+(J16*0.2)+(K16*0.2)+((1-L16)*0.2) -> 0.4296 | N16: 1796.1 | O16: 3473.95 | P16: =(O16/N16)^(1/5)-1 -> 0.14103406
A17: 38108 | B17: 1483.6 | C17: 11.94 | D17: 2.84 | E17: 5.274 | F17: =(E17/'Yearly GDP'!$B$3)*100 -> 867.86243 | G17: =1/C17 -> 0.083752094 | H17: =G17/E17*(100) -> 1.5880185 | I17: =_xlfn.PERCENTRANK.INC($C$3:$C$269,C17) -> 0.003 | J17: =_xlfn.PERCENTRANK.INC($D$3:$D$269,D17) -> 0.071 | K17: =_xlfn.PERCENTRANK.INC($H$3:$H$269,H17) -> 1 | L17: =_xlfn.PERCENTRANK.INC($F$3:$F$269,F17) -> 0.838 | M17: =(I17*0.4)+(J17*0.2)+(K17*0.2)+((1-L17)*0.2) -> 0.2478 | N17: 1483.6 | O17: 4448.95 | P17: =(O17/N17)^(1/5)-1 -> 0.24562736
A18: 38139 | B18: 1505.6 | C18: 12.64 | D18: 2.83 | E18: 5.85 | F18: =(E18/'Yearly GDP'!$B$3)*100 -> 962.64604 | G18: =1/C18 -> 0.079113924 | H18: =G18/E18*(100) -> 1.3523748 | I18: =_xlfn.PERCENTRANK.INC($C$3:$C$269,C18) -> 0.015 | J18: =_xlfn.PERCENTRANK.INC($D$3:$D$269,D18) -> 0.067 | K18: =_xlfn.PERCENTRANK.INC($H$3:$H$269,H18) -> 0.984 | L18: =_xlfn.PERCENTRANK.INC($F$3:$F$269,F18) -> 0.898 | M18: =(I18*0.4)+(J18*0.2)+(K18*0.2)+((1-L18)*0.2) -> 0.2366 | N18: 1505.6 | O18: 4291.1 | P18: =(O18/N18)^(1/5)-1 -> 0.23302478
A19: 38169 | B19: 1632.3 | C19: 13.63 | D19: 2.95 | E19: 6.164 | F19: =(E19/'Yearly GDP'!$B$3)*100 -> 1014.3163 | G19: =1/C19 -> 0.073367572 | H19: =G19/E19*(100) -> 1.1902591 | I19: =_xlfn.PERCENTRANK.INC($C$3:$C$269,C19) -> 0.048 | J19: =_xlfn.PERCENTRANK.INC($D$3:$D$269,D19) -> 0.112 | K19: =_xlfn.PERCENTRANK.INC($H$3:$H$269,H19) -> 0.951 | L19: =_xlfn.PERCENTRANK.INC($F$3:$F$269,F19) -> 0.958 | M19: =(I19*0.4)+(J19*0.2)+(K19*0.2)+((1-L19)*0.2) -> 0.2402 | N19: 1632.3 | O19: 4636.45 | P19: =(O19/N19)^(1/5)-1 -> 0.23218841
A20: 38200 | B20: 1631.75 | C20: 13.64 | D20: 2.95 | E20: 6.089 | F20: =(E20/'Yearly GDP'!$B$3)*100 -> 1001.9747 | G20: =1/C20 -> 0.073313783 | H20: =G20/E20*(100) -> 1.2040365 | I20: =_xlfn.PERCENTRANK.INC($C$3:$C$269,C20) -> 0.052 | J20: =_xlfn.PERCENTRANK.INC($D$3:$D$269,D20) -> 0.112 | K20: =_xlfn.PERCENTRANK.INC($H$3:$H$269,H20) -> 0.954 | L20: =_xlfn.PERCENTRANK.INC($F$3:$F$269,F20) -> 0.943 | M20: =(I20*0.4)+(J20*0.2)+(K20*0.2)+((1-L20)*0.2) -> 0.2454 | N20: 1631.75 | O20: 4662.1 | P20: =(O20/N20)^(1/5)-1 -> 0.2336319
A21: 38231 | B21: 1745.5 | C21: 14.59 | D21: 3.16 | E21: 6.244 | F21: =(E21/'Yearly GDP'!$B$3)*100 -> 1027.4807 | G21: =1/C21 -> 0.068540096 | H21: =G21/E21*(100) -> 1.0976953 | I21: =_xlfn.PERCENTRANK.INC($C$3:$C$269,C21) -> 0.075 | J21: =_xlfn.PERCENTRANK.INC($D$3:$D$269,D21) -> 0.214 | K21: =_xlfn.PERCENTRANK.INC($H$3:$H$269,H21) -> 0.939 | L21: =_xlfn.PERCENTRANK.INC($F$3:$F$269,F21) -> 0.969 | M21: =(I21*0.4)+(J21*0.2)+(K21*0.2)+((1-L21)*0.2) -> 0.2668 | N21: 1745.5 | O21: 5083.95 | P21: =(O21/N21)^(1/5)-1 -> 0.23838671
A22: 38261 | B22: 1786.9 | C22: 14.93 | D22: 3.08 | E22: 6.861 | F22: =(E22/'Yearly GDP'!$B$3)*100 -> 1129.011 | G22: =1/C22 -> 0.066979236 | H22: =G22/E22*(100) -> 0.9762314 | I22: =_xlfn.PERCENTRANK.INC($C$3:$C$269,C22) -> 0.09 | J22: =_xlfn.PERCENTRANK.INC($D$3:$D$269,D22) -> 0.176 | K22: =_xlfn.PERCENTRANK.INC($H$3:$H$269,H22) -> 0.89 | L22: =_xlfn.PERCENTRANK.INC($F$3:$F$269,F22) -> 0.988 | M22: =(I22*0.4)+(J22*0.2)+(K22*0.2)+((1-L22)*0.2) -> 0.2516 | N22: 1786.9 | O22: 4711.7 | P22: =(O22/N22)^(1/5)-1 -> 0.21399103
A23: 38292 | B23: 1958.8 | C23: 16.39 | D23: 3.38 | E23: 7.197 | F23: =(E23/'Yearly GDP'!$B$3)*100 -> 1184.3015 | G23: =1/C23 -> 0.061012813 | H23: =G23/E23*(100) -> 0.84775341 | I23: =_xlfn.PERCENTRANK.INC($C$3:$C$269,C23) -> 0.12 | J23: =_xlfn.PERCENTRANK.INC($D$3:$D$269,D23) -> 0.33 | K23: =_xlfn.PERCENTRANK.INC($H$3:$H$269,H23) -> 0.853 | L23: =_xlfn.PERCENTRANK.INC($F$3:$F$269,F23) -> 0.996 | M23: =(I23*0.4)+(J23*0.2)+(K23*0.2)+((1-L23)*0.2) -> 0.2854 | N23: 1958.8 | O23: 5032.7 | P23: =(O23/N23)^(1/5)-1 -> 0.20770869
A24: 38322 | B24: 2080.5 | C24: 15.32 | D24: 3.61 | E24: 6.706 | F24: =(E24/'Yearly GDP'!$B$3)*100 -> 1103.505 | G24: =1/C24 -> 0.065274151 | H24: =G24/E24*(100) -> 0.97336939 | I24: =_xlfn.PERCENTRANK.INC($C$3:$C$269,C24) -> 0.101 | J24: =_xlfn.PERCENTRANK.INC($D$3:$D$269,D24) -> 0.526 | K24: =_xlfn.PERCENTRANK.INC($H$3:$H$269,H24) -> 0.887 | L24: =_xlfn.PERCENTRANK.INC($F$3:$F$269,F24) -> 0.977 | M24: =(I24*0.4)+(J24*0.2)+(K24*0.2)+((1-L24)*0.2) -> 0.3276 | N24: 2080.5 | O24: 5201.05 | P24: =(O24/N24)^(1/5)-1 -> 0.2011152
A25: 38353 | B25: 2057.6 | C25: 14.68 | D25: 3.57 | E25: 6.703 | F25: =(E25/'Yearly GDP'!$B$4)*100 -> 945.2161 | G25: =1/C25 -> 0.068119891 | H25: =G25/E25*(100) -> 1.0162597 | I25: =_xlfn.PERCENTRANK.INC($C$3:$C$269,C25) -> 0.082 | J25: =_xlfn.PERCENTRANK.INC($D$3:$D$269,D25) -> 0.515 | K25: =_xlfn.PERCENTRANK.INC($H$3:$H$269,H25) -> 0.906 | L25: =_xlfn.PERCENTRANK.INC($F$3:$F$269,F25) -> 0.89 | M25: =(I25*0.4)+(J25*0.2)+(K25*0.2)+((1-L25)*0.2) -> 0.339 | N25: 2057.6 | O25: 4882.05 | P25: =(O25/N25)^(1/5)-1 -> 0.18863429
A26: 38384 | B26: 2103.25 | C26: 15.02 | D26: 3.92 | E26: 6.549 | F26: =(E26/'Yearly GDP'!$B$4)*100 -> 923.49996 | G26: =1/C26 -> 0.066577896 | H26: =G26/E26*(100) -> 1.0166116 | I26: =_xlfn.PERCENTRANK.INC($C$3:$C$269,C26) -> 0.097 | J26: =_xlfn.PERCENTRANK.INC($D$3:$D$269,D26) -> 0.721 | K26: =_xlfn.PERCENTRANK.INC($H$3:$H$269,H26) -> 0.909 | L26: =_xlfn.PERCENTRANK.INC($F$3:$F$269,F26) -> 0.868 | M26: =(I26*0.4)+(J26*0.2)+(K26*0.2)+((1-L26)*0.2) -> 0.3912 | N26: 2103.25 | O26: 4922.3 | P26: =(O26/N26)^(1/5)-1 -> 0.18537411
A27: 38412 | B27: 2035.65 | C27: 14.6 | D27: 3.82 | E27: 6.676 | F27: =(E27/'Yearly GDP'!$B$4)*100 -> 941.40873 | G27: =1/C27 -> 0.068493151 | H27: =G27/E27*(100) -> 1.0259609 | I27: =_xlfn.PERCENTRANK.INC($C$3:$C$269,C27) -> 0.078 | J27: =_xlfn.PERCENTRANK.INC($D$3:$D$269,D27) -> 0.676 | K27: =_xlfn.PERCENTRANK.INC($H$3:$H$269,H27) -> 0.917 | L27: =_xlfn.PERCENTRANK.INC($F$3:$F$269,F27) -> 0.887 | M27: =(I27*0.4)+(J27*0.2)+(K27*0.2)+((1-L27)*0.2) -> 0.3724 | N27: 2035.65 | O27: 5249.1 | P27: =(O27/N27)^(1/5)-1 -> 0.20858263
A28: 38443 | B28: 1902.5 | C28: 13.27 | D28: 3.56 | E28: 7.239 | F28: =(E28/'Yearly GDP'!$B$4)*100 -> 1020.7995 | G28: =1/C28 -> 0.07535795 | H28: =G28/E28*(100) -> 1.0409995 | I28: =_xlfn.PERCENTRANK.INC($C$3:$C$269,C28) -> 0.037 | J28: =_xlfn.PERCENTRANK.INC($D$3:$D$269,D28) -> 0.503 | K28: =_xlfn.PERCENTRANK.INC($H$3:$H$269,H28) -> 0.924 | L28: =_xlfn.PERCENTRANK.INC($F$3:$F$269,F28) -> 0.962 | M28: =(I28*0.4)+(J28*0.2)+(K28*0.2)+((1-L28)*0.2) -> 0.3078 | N28: 1902.5 | O28: 5278 | P28: =(O28/N28)^(1/5)-1 -> 0.22639097
A29: 38473 | B29: 2087.55 | C29: 13.94 | D29: 3.91 | E29: 6.979 | F29: =(E29/'Yearly GDP'!$B$4)*100 -> 984.13594 | G29: =1/C29 -> 0.071736011 | H29: =G29/E29*(100) -> 1.0278838 | I29: =_xlfn.PERCENTRANK.INC($C$3:$C$269,C29) -> 0.056 | J29: =_xlfn.PERCENTRANK.INC($D$3:$D$269,D29) -> 0.718 | K29: =_xlfn.PERCENTRANK.INC($H$3:$H$269,H29) -> 0.921 | L29: =_xlfn.PERCENTRANK.INC($F$3:$F$269,F29) -> 0.909 | M29: =(I29*0.4)+(J29*0.2)+(K29*0.2)+((1-L29)*0.2) -> 0.3684 | N29: 2087.55 | O29: 5086.3 | P29: =(O29/N29)^(1/5)-1 -> 0.19495903
A30: 38504 | B30: 2220.6 | C30: 14.31 | D30: 3.98 | E30: 6.907 | F30: =(E30/'Yearly GDP'!$B$4)*100 -> 973.98294 | G30: =1/C30 -> 0.069881202 | H30: =G30/E30*(100) -> 1.0117446 | I30: =_xlfn.PERCENTRANK.INC($C$3:$C$269,C30) -> 0.071 | J30: =_xlfn.PERCENTRANK.INC($D$3:$D$269,D30) -> 0.74 | K30: =_xlfn.PERCENTRANK.INC($H$3:$H$269,H30) -> 0.902 | L30: =_xlfn.PERCENTRANK.INC($F$3:$F$269,F30) -> 0.902 | M30: =(I30*0.4)+(J30*0.2)+(K30*0.2)+((1-L30)*0.2) -> 0.3764 | N30: 2220.6 | O30: 5312.5 | P30: =(O30/N30)^(1/5)-1 -> 0.19059957
A31: 38534 | B31: 2312.3 | C31: 14.1 | D31: 3.86 | E31: 6.96 | F31: =(E31/'Yearly GDP'!$B$4)*100 -> 981.45667 | G31: =1/C31 -> 0.070921986 | H31: =G31/E31*(100) -> 1.018994 | I31: =_xlfn.PERCENTRANK.INC($C$3:$C$269,C31) -> 0.06 | J31: =_xlfn.PERCENTRANK.INC($D$3:$D$269,D31) -> 0.691 | K31: =_xlfn.PERCENTRANK.INC($H$3:$H$269,H31) -> 0.913 | L31: =_xlfn.PERCENTRANK.INC($F$3:$F$269,F31) -> 0.906 | M31: =(I31*0.4)+(J31*0.2)+(K31*0.2)+((1-L31)*0.2) -> 0.3636 | N31: 2312.3 | O31: 5367.6 | P31: =(O31/N31)^(1/5)-1 -> 0.18344259
A32: 38565 | B32: 2384.65 | C32: 14.78 | D32: 3.89 | E32: 7.094 | F32: =(E32/'Yearly GDP'!$B$4)*100 -> 1000.3525 | G32: =1/C32 -> 0.067658999 | H32: =G32/E32*(100) -> 0.95374963 | I32: =_xlfn.PERCENTRANK.INC($C$3:$C$269,C32) -> 0.086 | J32: =_xlfn.PERCENTRANK.INC($D$3:$D$269,D32) -> 0.706 | K32: =_xlfn.PERCENTRANK.INC($H$3:$H$269,H32) -> 0.872 | L32: =_xlfn.PERCENTRANK.INC($F$3:$F$269,F32) -> 0.932 | M32: =(I32*0.4)+(J32*0.2)+(K32*0.2)+((1-L32)*0.2) -> 0.3636 | N32: 2384.65 | O32: 5402.4 | P32: =(O32/N32)^(1/5)-1 -> 0.17769388
A33: 38596 | B33: 2601.4 | C33: 16.15 | D33: 4.01 | E33: 7.101 | F33: =(E33/'Yearly GDP'!$B$4)*100 -> 1001.3396 | G33: =1/C33 -> 0.061919505 | H33: =G33/E33*(100) -> 0.87198288 | I33: =_xlfn.PERCENTRANK.INC($C$3:$C$269,C33) -> 0.116 | J33: =_xlfn.PERCENTRANK.INC($D$3:$D$269,D33) -> 0.751 | K33: =_xlfn.PERCENTRANK.INC($H$3:$H$269,H33) -> 0.857 | L33: =_xlfn.PERCENTRANK.INC($F$3:$F$269,F33) -> 0.939 | M33: =(I33*0.4)+(J33*0.2)+(K33*0.2)+((1-L33)*0.2) -> 0.3802 | N33: 2601.4 | O33: 6029.95 | P33: =(O33/N33)^(1/5)-1 -> 0.18309962
A34: 38626 | B34: 2370.95 | C34: 14.23 | D34: 3.63 | E34: 7.099 | F34: =(E34/'Yearly GDP'!$B$4)*100 -> 1001.0576 | G34: =1/C34 -> 0.070274069 | H34: =G34/E34*(100) -> 0.98991504 | I34: =_xlfn.PERCENTRANK.INC($C$3:$C$269,C34) -> 0.063 | J34: =_xlfn.PERCENTRANK.INC($D$3:$D$269,D34) -> 0.545 | K34: =_xlfn.PERCENTRANK.INC($H$3:$H$269,H34) -> 0.894 | L34: =_xlfn.PERCENTRANK.INC($F$3:$F$269,F34) -> 0.936 | M34: =(I34*0.4)+(J34*0.2)+(K34*0.2)+((1-L34)*0.2) -> 0.3258 | N34: 2370.95 | O34: 6017.7 | P34: =(O34/N34)^(1/5)-1 -> 0.20476302
A35: 38657 | B35: 2652.25 | C35: 15.95 | D35: 4.06 | E35: 7.083 | F35: =(E35/'Yearly GDP'!$B$4)*100 -> 998.80138 | G35: =1/C35 -> 0.062695925 | H35: =G35/E35*(100) -> 0.88516059 | I35: =_xlfn.PERCENTRANK.INC($C$3:$C$269,C35) -> 0.112 | J35: =_xlfn.PERCENTRANK.INC($D$3:$D$269,D35) -> 0.774 | K35: =_xlfn.PERCENTRANK.INC($H$3:$H$269,H35) -> 0.86 | L35: =_xlfn.PERCENTRANK.INC($F$3:$F$269,F35) -> 0.924 | M35: =(I35*0.4)+(J35*0.2)+(K35*0.2)+((1-L35)*0.2) -> 0.3868 | N35: 2652.25 | O35: 5862.7 | P35: =(O35/N35)^(1/5)-1 -> 0.17191643
A36: 38687 | B36: 2836.55 | C36: 17.16 | D36: 4.37 | E36: 7.11 | F36: =(E36/'Yearly GDP'!$B$4)*100 -> 1002.6088 | G36: =1/C36 -> 0.058275058 | H36: =G36/E36*(100) -> 0.81962107 | I36: =_xlfn.PERCENTRANK.INC($C$3:$C$269,C36) -> 0.154 | J36: =_xlfn.PERCENTRANK.INC($D$3:$D$269,D36) -> 0.853 | K36: =_xlfn.PERCENTRANK.INC($H$3:$H$269,H36) -> 0.845 | L36: =_xlfn.PERCENTRANK.INC($F$3:$F$269,F36) -> 0.947 | M36: =(I36*0.4)+(J36*0.2)+(K36*0.2)+((1-L36)*0.2) -> 0.4118 | N36: 2836.55 | O36: 6134.5 | P36: =(O36/N36)^(1/5)-1 -> 0.16680356
A37: 38718 | B37: 3001.1 | C37: 17.9 | D37: 4.53 | E37: 7.372 | F37: =(E37/'Yearly GDP'!$B$5)*100 -> 898.60796 | G37: =1/C37 -> 0.055865922 | H37: =G37/E37*(100) -> 0.75781229 | I37: =_xlfn.PERCENTRANK.INC($C$3:$C$269,C37) -> 0.21 | J37: =_xlfn.PERCENTRANK.INC($D$3:$D$269,D37) -> 0.894 | K37: =_xlfn.PERCENTRANK.INC($H$3:$H$269,H37) -> 0.842 | L37: =_xlfn.PERCENTRANK.INC($F$3:$F$269,F37) -> 0.849 | M37: =(I37*0.4)+(J37*0.2)+(K37*0.2)+((1-L37)*0.2) -> 0.4614 | N37: 3001.1 | O37: 5505.9 | P37: =(O37/N37)^(1/5)-1 -> 0.12904063
A38: 38749 | B38: 3074.7 | C38: 18.27 | D38: 4.64 | E38: 7.393 | F38: =(E38/'Yearly GDP'!$B$5)*100 -> 901.16775 | G38: =1/C38 -> 0.054734537 | H38: =G38/E38*(100) -> 0.74035625 | I38: =_xlfn.PERCENTRANK.INC($C$3:$C$269,C38) -> 0.236 | J38: =_xlfn.PERCENTRANK.INC($D$3:$D$269,D38) -> 0.906 | K38: =_xlfn.PERCENTRANK.INC($H$3:$H$269,H38) -> 0.815 | L38: =_xlfn.PERCENTRANK.INC($F$3:$F$269,F38) -> 0.857 | M38: =(I38*0.4)+(J38*0.2)+(K38*0.2)+((1-L38)*0.2) -> 0.4672 | N38: 3074.7 | O38: 5333.25 | P38: =(O38/N38)^(1/5)-1 -> 0.1164463
A39: 38777 | B39: 3402.55 | C39: 20.26 | D39: 5.15 | E39: 7.55 | F39: =(E39/'Yearly GDP'!$B$5)*100 -> 920.30522 | G39: =1/C39 -> 0.049358342 | H39: =G39/E39*(100) -> 0.65375287 | I39: =_xlfn.PERCENTRANK.INC($C$3:$C$269,C39) -> 0.357 | J39: =_xlfn.PERCENTRANK.INC($D$3:$D$269,D39) -> 0.951 | K39: =_xlfn.PERCENTRANK.INC($H$3:$H$269,H39) -> 0.605 | L39: =_xlfn.PERCENTRANK.INC($F$3:$F$269,F39) -> 0.864 | M39: =(I39*0.4)+(J39*0.2)+(K39*0.2)+((1-L39)*0.2) -> 0.4812 | N39: 3402.55 | O39: 5833.75 | P39: =(O39/N39)^(1/5)-1 -> 0.113855
A40: 38808 | B40: 3557.6 | C40: 20.31 | D40: 5.39 | E40: 7.39 | F40: =(E40/'Yearly GDP'!$B$5)*100 -> 900.80207 | G40: =1/C40 -> 0.049236829 | H40: =G40/E40*(100) -> 0.66626291 | I40: =_xlfn.PERCENTRANK.INC($C$3:$C$269,C40) -> 0.36 | J40: =_xlfn.PERCENTRANK.INC($D$3:$D$269,D40) -> 0.973 | K40: =_xlfn.PERCENTRANK.INC($H$3:$H$269,H40) -> 0.672 | L40: =_xlfn.PERCENTRANK.INC($F$3:$F$269,F40) -> 0.853 | M40: =(I40*0.4)+(J40*0.2)+(K40*0.2)+((1-L40)*0.2) -> 0.5024 | N40: 3557.6 | O40: 5749.5 | P40: =(O40/N40)^(1/5)-1 -> 0.10076495
...

Sheet Yearly GDP
A1: Year | B1: (USD) in Trillions | C1: GDP | D1: CY changes
A2: 2002 | B2: =C2/1000 -> 0.51494 | C2: 514.94
A3: 2003 | B3: 0.6077 | C3: =B3*1000 -> 607.7 | D3: =(C3-C2)/C2 -> 0.18013749
A4: 2004 | B4: 0.70915 | C4: =B4*1000 -> 709.15 | D4: =(C4-C3)/C3 -> 0.16694092
A5: 2005 | B5: 0.82038 | C5: =B5*1000 -> 820.38 | D5: =(C5-C4)/C4 -> 0.15684975
A6: 2006 | B6: 0.94026 | C6: =B6*1000 -> 940.26 | D6: =(C6-C5)/C5 -> 0.1461274
A7: 2007 | B7: 1.22 | C7: =B7*1000 -> 1220 | D7: =(C7-C6)/C6 -> 0.29751345
A8: 2008 | B8: 1.2 | C8: =B8*1000 -> 1200 | D8: =(C8-C7)/C7 -> -0.016393443
A9: 2009 | B9: 1.34 | C9: =B9*1000 -> 1340 | D9: =(C9-C8)/C8 -> 0.11666667
A10: 2010 | B10: 1.68 | C10: =B10*1000 -> 1680 | D10: =(C10-C9)/C9 -> 0.25373134
A11: 2011 | B11: 1.82 | C11: =B11*1000 -> 1820 | D11: =(C11-C10)/C10 -> 0.083333333
A12: 2012 | B12: 1.83 | C12: =B12*1000 -> 1830 | D12: =(C12-C11)/C11 -> 0.0054945055
A13: 2013 | B13: 1.86 | C13: =B13*1000 -> 1860 | D13: =(C13-C12)/C12 -> 0.016393443
A14: 2014 | B14: 2.04 | C14: =B14*1000 -> 2040 | D14: =(C14-C13)/C13 -> 0.096774194
... A24: 2024 | B24: 3.68 | C24: =B24*1000 -> 3680 | D24: =(C24-C23)/C23 -> 0.030812325
A25: 2025
