Workbook

Sheet Yearly
A1: Year | B1: Nifty 50 | C1: Nifty PE | D1: Nifty PB | E1: 10yr Yeild | F1: Buffett Indicator | G1: Earning Yeild | H1: BEER ratio | I1: Percentile | M1: Valuation Score | N1: Nifty | O1: Nifty aft 5yr | P1: Future 5yr CAGR
I2: PE | J2: PB | K2: BEER | L2: Buffett
A3: 2000 | B3: 1263.55 | C3: 19.2 | D3: 4.14 | E3: 0.1088 | F3: 48.17475 | G3: =(1/C3) -> 0.052083333 | H3: =G3/E3 -> 0.47870711 | I3: =_xlfn.PERCENTRANK.INC($C$3:$C$28,C3) -> 0.32 | J3: =_xlfn.PERCENTRANK.INC($D$3:$D$28,D3) -> 0.8 | K3: =_xlfn.PERCENTRANK.INC($H$3:$H$28,H3) -> 0.08 | L3: =_xlfn.PERCENTRANK.INC($F$3:$F$28,F3) -> 0.08 | M3: =(I3*0.4)+(J3*0.2)+(K3*0.2)+((1-L3)*0.2) -> 0.488 | N3: 1263.55 | O3: 2836.55 | P3: =(O3/N3)^(1/5)-1 -> 0.17554593
A4: 2001 | B4: 1059.05 | C4: 15.35 | D4: 2.38 | E4: 0.07939 | F4: 30.646752 | G4: =(1/C4) -> 0.06514658 | H4: =G4/E4 -> 0.82058924 | I4: =_xlfn.PERCENTRANK.INC($C$3:$C$28,C4) -> 0.12 | J4: =_xlfn.PERCENTRANK.INC($D$3:$D$28,D4) -> 0 | K4: =_xlfn.PERCENTRANK.INC($H$3:$H$28,H4) -> 0.84 | L4: =_xlfn.PERCENTRANK.INC($F$3:$F$28,F4) -> 0 | M4: =(I4*0.4)+(J4*0.2)+(K4*0.2)+((1-L4)*0.2) -> 0.416 | N4: 1059.05 | O4: 3966.4 | P4: =(O4/N4)^(1/5)-1 -> 0.30225493
A5: 2002 | B5: 1093.5 | C5: 14.83 | D5: 2.39 | E5: 0.06083 | F5: 33.438061 | G5: =(1/C5) -> 0.067430883 | H5: =G5/E5 -> 1.1085136 | I5: =_xlfn.PERCENTRANK.INC($C$3:$C$28,C5) -> 0.04 | J5: =_xlfn.PERCENTRANK.INC($D$3:$D$28,D5) -> 0.04 | K5: =_xlfn.PERCENTRANK.INC($H$3:$H$28,H5) -> 0.96 | L5: =_xlfn.PERCENTRANK.INC($F$3:$F$28,F5) -> 0.04 | M5: =(I5*0.4)+(J5*0.2)+(K5*0.2)+((1-L5)*0.2) -> 0.408 | N5: 1093.5 | O5: 6138.6 | P5: =(O5/N5)^(1/5)-1 -> 0.41205011
A6: 2003 | B6: 1879.75 | C6: 20.73 | D6: 4.05 | E6: 0.05122 | F6: 50.846571 | G6: =(1/C6) -> 0.048239267 | H6: =G6/E6 -> 0.94180529 | I6: =_xlfn.PERCENTRANK.INC($C$3:$C$28,C6) -> 0.36 | J6: =_xlfn.PERCENTRANK.INC($D$3:$D$28,D6) -> 0.76 | K6: =_xlfn.PERCENTRANK.INC($H$3:$H$28,H6) -> 0.88 | L6: =_xlfn.PERCENTRANK.INC($F$3:$F$28,F6) -> 0.12 | M6: =(I6*0.4)+(J6*0.2)+(K6*0.2)+((1-L6)*0.2) -> 0.648 | N6: 1879.75 | O6: 2959.15 | P6: =(O6/N6)^(1/5)-1 -> 0.09499813
A7: 2004 | B7: 2080.5 | C7: 15.32 | D7: 3.61 | E7: 0.06706 | F7: 58.597294 | G7: =(1/C7) -> 0.065274151 | H7: =G7/E7 -> 0.97336939 | I7: =_xlfn.PERCENTRANK.INC($C$3:$C$28,C7) -> 0.08 | J7: =_xlfn.PERCENTRANK.INC($D$3:$D$28,D7) -> 0.52 | K7: =_xlfn.PERCENTRANK.INC($H$3:$H$28,H7) -> 0.92 | L7: =_xlfn.PERCENTRANK.INC($F$3:$F$28,F7) -> 0.16 | M7: =(I7*0.4)+(J7*0.2)+(K7*0.2)+((1-L7)*0.2) -> 0.488 | N7: 2080.5 | O7: 5201.05 | P7: =(O7/N7)^(1/5)-1 -> 0.2011152
A8: 2005 | B8: 2836.55 | C8: 17.16 | D8: 4.37 | E8: 0.0711 | F8: 76.152115 | G8: =(1/C8) -> 0.058275058 | H8: =G8/E8 -> 0.81962107 | I8: =_xlfn.PERCENTRANK.INC($C$3:$C$28,C8) -> 0.2 | J8: =_xlfn.PERCENTRANK.INC($D$3:$D$28,D8) -> 0.88 | K8: =_xlfn.PERCENTRANK.INC($H$3:$H$28,H8) -> 0.8 | L8: =_xlfn.PERCENTRANK.INC($F$3:$F$28,F8) -> 0.4 | M8: =(I8*0.4)+(J8*0.2)+(K8*0.2)+((1-L8)*0.2) -> 0.536 | N8: 2836.55 | O8: 6134.5 | P8: =(O8/N8)^(1/5)-1 -> 0.16680356
A9: 2006 | B9: 3966.4 | C9: 21.26 | D9: 5.07 | E9: 0.07619 | F9: 95.215152 | G9: =(1/C9) -> 0.047036689 | H9: =G9/E9 -> 0.6173604 | I9: =_xlfn.PERCENTRANK.INC($C$3:$C$28,C9) -> 0.44 | J9: =_xlfn.PERCENTRANK.INC($D$3:$D$28,D9) -> 0.96 | K9: =_xlfn.PERCENTRANK.INC($H$3:$H$28,H9) -> 0.48 | L9: =_xlfn.PERCENTRANK.INC($F$3:$F$28,F9) -> 0.56 | M9: =(I9*0.4)+(J9*0.2)+(K9*0.2)+((1-L9)*0.2) -> 0.552 | N9: 3966.4 | O9: 4624.3 | P9: =(O9/N9)^(1/5)-1 -> 0.031169119
A10: 2007 | B10: 6138.6 | C10: 27.62 | D10: 6.39 | E10: 0.07791 | F10: 161.23945 | G10: =(1/C10) -> 0.036205648 | H10: =G10/E10 -> 0.46471118 | I10: =_xlfn.PERCENTRANK.INC($C$3:$C$28,C10) -> 0.92 | J10: =_xlfn.PERCENTRANK.INC($D$3:$D$28,D10) -> 1 | K10: =_xlfn.PERCENTRANK.INC($H$3:$H$28,H10) -> 0.04 | L10: =_xlfn.PERCENTRANK.INC($F$3:$F$28,F10) -> 1 | M10: =(I10*0.4)+(J10*0.2)+(K10*0.2)+((1-L10)*0.2) -> 0.576 | N10: 6138.6 | O10: 5905.1 | P10: =(O10/N10)^(1/5)-1 -> -0.0077260631
A11: 2008 | B11: 2959.15 | C11: 12.97 | D11: 2.44 | E11: 0.0526 | F11: 66.003104 | G11: =(1/C11) -> 0.077101002 | H11: =G11/E11 -> 1.4657985 | I11: =_xlfn.PERCENTRANK.INC($C$3:$C$28,C11) -> 0 | J11: =_xlfn.PERCENTRANK.INC($D$3:$D$28,D11) -> 0.08 | K11: =_xlfn.PERCENTRANK.INC($H$3:$H$28,H11) -> 1 | L11: =_xlfn.PERCENTRANK.INC($F$3:$F$28,F11) -> 0.2 | M11: =(I11*0.4)+(J11*0.2)+(K11*0.2)+((1-L11)*0.2) -> 0.376 | N11: 2959.15 | O11: 6304 | P11: =(O11/N11)^(1/5)-1 -> 0.16329496
A12: 2009 | B12: 5201.05 | C12: 23.17 | D12: 3.65 | E12: 0.07679 | F12: 101.89449 | G12: =(1/C12) -> 0.043159258 | H12: =G12/E12 -> 0.56204268 | I12: =_xlfn.PERCENTRANK.INC($C$3:$C$28,C12) -> 0.68 | J12: =_xlfn.PERCENTRANK.INC($D$3:$D$28,D12) -> 0.56 | K12: =_xlfn.PERCENTRANK.INC($H$3:$H$28,H12) -> 0.28 | L12: =_xlfn.PERCENTRANK.INC($F$3:$F$28,F12) -> 0.72 | M12: =(I12*0.4)+(J12*0.2)+(K12*0.2)+((1-L12)*0.2) -> 0.496 | N12: 5201.05 | O12: 8282.7 | P12: =(O12/N12)^(1/5)-1 -> 0.097529445
A13: 2010 | B13: 6134.5 | C13: 24.48 | D13: 3.87 | E13: 0.07913 | F13: 105.18295 | G13: =(1/C13) -> 0.040849673 | H13: =G13/E13 -> 0.51623497 | I13: =_xlfn.PERCENTRANK.INC($C$3:$C$28,C13) -> 0.8 | J13: =_xlfn.PERCENTRANK.INC($D$3:$D$28,D13) -> 0.68 | K13: =_xlfn.PERCENTRANK.INC($H$3:$H$28,H13) -> 0.16 | L13: =_xlfn.PERCENTRANK.INC($F$3:$F$28,F13) -> 0.76 | M13: =(I13*0.4)+(J13*0.2)+(K13*0.2)+((1-L13)*0.2) -> 0.536 | N13: 6134.5 | O13: 7964.35 | P13: =(O13/N13)^(1/5)-1 -> 0.053596291
A14: 2011 | B14: 4624.3 | C14: 16.75 | D14: 2.76 | E14: 0.0856 | F14: 68.270064 | G14: =(1/C14) -> 0.059701493 | H14: =G14/E14 -> 0.69744734 | I14: =_xlfn.PERCENTRANK.INC($C$3:$C$28,C14) -> 0.16 | J14: =_xlfn.PERCENTRANK.INC($D$3:$D$28,D14) -> 0.12 | K14: =_xlfn.PERCENTRANK.INC($H$3:$H$28,H14) -> 0.72 | L14: =_xlfn.PERCENTRANK.INC($F$3:$F$28,F14) -> 0.28 | M14: =(I14*0.4)+(J14*0.2)+(K14*0.2)+((1-L14)*0.2) -> 0.376 | N14: 4624.3 | O14: 8185.8 | P14: =(O14/N14)^(1/5)-1 -> 0.12099332
... A23: 2020 | B23: 13981.75 | C23: 38.45 | D23: 3.96 | E23: 0.05894 | F23: 95.424502 | G23: =(1/C23) -> 0.026007802 | H23: =G23/E23 -> 0.44125895 | I23: =_xlfn.PERCENTRANK.INC($C$3:$C$28,C23) -> 1 | J23: =_xlfn.PERCENTRANK.INC($D$3:$D$28,D23) -> 0.72 | K23: =_xlfn.PERCENTRANK.INC($H$3:$H$28,H23) -> 0 | L23: =_xlfn.PERCENTRANK.INC($F$3:$F$28,F23) -> 0.6 | M23: =(I23*0.4)+(J23*0.2)+(K23*0.2)+((1-L23)*0.2) -> 0.624 | N23: 13981.75 | O23: 26129.6 | P23: =(O23/N23)^(1/5)-1 -> 0.13322004
A24: 2021 | B24: 17354.05 | C24: 24.11 | D24: 4.37 | E24: 0.06454 | F24: 112.02132 | G24: =(1/C24) -> 0.041476566 | H24: =G24/E24 -> 0.64264899 | I24: =_xlfn.PERCENTRANK.INC($C$3:$C$28,C24) -> 0.76 | J24: =_xlfn.PERCENTRANK.INC($D$3:$D$28,D24) -> 0.88 | K24: =_xlfn.PERCENTRANK.INC($H$3:$H$28,H24) -> 0.56 | L24: =_xlfn.PERCENTRANK.INC($F$3:$F$28,F24) -> 0.8 | M24: =(I24*0.4)+(J24*0.2)+(K24*0.2)+((1-L24)*0.2) -> 0.632 | N24: 17354.05
A25: 2022 | B25: 18105.3 | C25: 21.79 | D25: 4.25 | E25: 0.07327 | F25: 101.23306 | G25: =(1/C25) -> 0.045892611 | H25: =G25/E25 -> 0.62634927 | I25: =_xlfn.PERCENTRANK.INC($C$3:$C$28,C25) -> 0.52 | J25: =_xlfn.PERCENTRANK.INC($D$3:$D$28,D25) -> 0.84 | K25: =_xlfn.PERCENTRANK.INC($H$3:$H$28,H25) -> 0.52 | L25: =_xlfn.PERCENTRANK.INC($F$3:$F$28,F25) -> 0.68 | M25: =(I25*0.4)+(J25*0.2)+(K25*0.2)+((1-L25)*0.2) -> 0.544 | N25: 18105.3
A26: 2023 | B26: 21731.4 | C26: 23.17 | D26: 3.83 | E26: 0.07176 | F26: 119.28387 | G26: =(1/C26) -> 0.043159258 | H26: =G26/E26 -> 0.60143893 | I26: =_xlfn.PERCENTRANK.INC($C$3:$C$28,C26) -> 0.68 | J26: =_xlfn.PERCENTRANK.INC($D$3:$D$28,D26) -> 0.64 | K26: =_xlfn.PERCENTRANK.INC($H$3:$H$28,H26) -> 0.36 | L26: =_xlfn.PERCENTRANK.INC($F$3:$F$28,F26) -> 0.84 | M26: =(I26*0.4)+(J26*0.2)+(K26*0.2)+((1-L26)*0.2) -> 0.504 | N26: 21731.4
A27: 2024 | B27: 23644.8 | C27: 21.79 | D27: 3.53 | E27: 0.06759 | F27: 131.24143 | G27: =(1/C27) -> 0.045892611 | H27: =G27/E27 -> 0.67898522 | I27: =_xlfn.PERCENTRANK.INC($C$3:$C$28,C27) -> 0.52 | J27: =_xlfn.PERCENTRANK.INC($D$3:$D$28,D27) -> 0.4 | K27: =_xlfn.PERCENTRANK.INC($H$3:$H$28,H27) -> 0.68 | L27: =_xlfn.PERCENTRANK.INC($F$3:$F$28,F27) -> 0.88 | M27: =(I27*0.4)+(J27*0.2)+(K27*0.2)+((1-L27)*0.2) -> 0.448 | N27: 23644.8
A28: 2025 | B28: 26129.6 | C28: 22.75 | D28: 3.55 | E28: 0.06588 | F28: 137.7 | G28: =(1/C28) -> 0.043956044 | H28: =G28/E28 -> 0.66721378 | I28: =_xlfn.PERCENTRANK.INC($C$3:$C$28,C28) -> 0.64 | J28: =_xlfn.PERCENTRANK.INC($D$3:$D$28,D28) -> 0.44 | K28: =_xlfn.PERCENTRANK.INC($H$3:$H$28,H28) -> 0.64 | L28: =_xlfn.PERCENTRANK.INC($F$3:$F$28,F28) -> 0.92 | M28: =(I28*0.4)+(J28*0.2)+(K28*0.2)+((1-L28)*0.2) -> 0.488 | N28: 26129.6

Sheet Monthly
A1: S.no | B1: Date | C1: Market Cap | D1: US $ | E1: USD/INR | F1: Trillion | G1: Market Cap to GDP | H1: BEER | I1: Nifty 50 Earning Yield | J1: NIFTY 50 EPS | K1: India 10Yr Yield | L1: Nifty 50 | M1: Price to Book | N1: Equity Earnings Yield vs 10 Year G Sec Yield Gap | O1: Nifty 50 pe | P1: US 10yr Bond | Q1: India yr- US 10yr | R1: Dollar index | S1: PREITY Ratio | T1: 91 day T Bill | U1: Nifty Midcap 150 | V1: Midcap 150 PE | W1: Midcap EPS | X1: Midcap Earning Yield | Y1: Nifty Smallcap 250 | Z1: Smallcap 250 PE | AA1: Smallcap EPS | AB1: Smallcap Earning Yield
A2: 1 | B2: 37681 | C2: 537133 | D2: =C2/E2 -> 11312.826 | E2: 47.48 | F2: =(D2/100000) -> 0.11312826 | G2: =(F2/'Yearly GDP'!$B$2)*100 -> 21.969213 | H2: =(K2/I2) -> 0.8185672 | I2: =(J2/L2)*100 -> 7.4850299 | J2: =L2/O2 -> 73.218563 | K2: 6.127 | L2: 978.2 | M2: 2.15 | N2: =K2-I2 -> -1.3580299 | O2: 13.36 | P2: 3.802 | Q2: =K2-P2 -> 2.325 | R2: 99.49 | S2: =(O2*T2) -> 76.82 | T2: 5.75
A3: 2 | B3: 37712 | C3: 530630 | D3: =C3/E3 -> 11213.652 | E3: 47.32 | F3: =(D3/100000) -> 0.11213652 | G3: =(F3/'Yearly GDP'!$B$2)*100 -> 21.776618 | H3: =(K3/I3) -> 0.7728948 | I3: =(J3/L3)*100 -> 7.6103501 | J3: =L3/O3 -> 71.084475 | K3: 5.882 | L3: 934.05 | M3: 2.11 | N3: =K3-I3 -> -1.7283501 | O3: 13.14 | P3: 3.84 | Q3: =K3-P3 -> 2.042 | R3: 97.38 | S3: =(O3*T3) -> 60.444 | T3: 4.6
A4: 3 | B4: 37742 | C4: 612030 | D4: =C4/E4 -> 13016.376 | E4: 47.02 | F4: =(D4/100000) -> 0.13016376 | G4: =(F4/'Yearly GDP'!$B$2)*100 -> 25.277461 | H4: =(K4/I4) -> 0.6748845 | I4: =(J4/L4)*100 -> 8.583691 | J4: =L4/O4 -> 86.420601 | K4: 5.793 | L4: 1006.8 | M4: 2.17 | N4: =K4-I4 -> -2.790691 | O4: 11.65 | P4: 3.373 | Q4: =K4-P4 -> 2.42 | R4: 93.31 | S4: =(O4*T4) -> 54.056 | T4: 4.64
A5: 4 | B5: 37773 | C5: 678550 | D5: =C5/E5 -> 14620.771 | E5: 46.41 | F5: =(D5/100000) -> 0.14620771 | G5: =(F5/'Yearly GDP'!$B$2)*100 -> 28.393155 | H5: =(K5/I5) -> 0.742035 | I5: =(J5/L5)*100 -> 7.7220077 | J5: =L5/O5 -> 87.579151 | K5: 5.73 | L5: 1134.15 | M5: 2.44 | N5: =K5-I5 -> -1.9920077 | O5: 12.95 | P5: 3.516 | Q5: =K5-P5 -> 2.214 | R5: 95.11 | S5: =(O5*T5) -> 64.491 | T5: 4.98
A6: 5 | B6: 37803 | C6: 719145.05 | D6: =C6/E6 -> 15577.711 | E6: 46.165 | F6: =(D6/100000) -> 0.15577711 | G6: =(F6/'Yearly GDP'!$B$2)*100 -> 30.251508 | H6: =(K6/I6) -> 0.7210944 | I6: =(J6/L6)*100 -> 7.788162 | J6: =L6/O6 -> 92.355919 | K6: 5.616 | L6: 1185.85 | M6: 2.55 | N6: =K6-I6 -> -2.172162 | O6: 12.84 | P6: 4.41 | Q6: =K6-P6 -> 1.206 | R6: 97.14 | S6: =(O6*T6) -> 60.99 | T6: 4.75
A7: 6 | B7: 37834 | C7: 836651.05 | D7: =C7/E7 -> 18243.59 | E7: 45.86 | F7: =(D7/100000) -> 0.1824359 | G7: =(F7/'Yearly GDP'!$B$2)*100 -> 35.428575 | H7: =(K7/I7) -> 0.789659 | I7: =(J7/L7)*100 -> 6.6889632 | J7: =L7/O7 -> 90.73913 | K7: 5.282 | L7: 1356.55 | M7: 2.92 | N7: =K7-I7 -> -1.4069632 | O7: 14.95 | P7: 4.47 | Q7: =K7-P7 -> 0.812 | R7: 98.1 | S7: =(O7*T7) -> 69.5175 | T7: 4.65
A8: 7 | B8: 37865 | C8: 863481 | D8: =C8/E8 -> 18915.246 | E8: 45.65 | F8: =(D8/100000) -> 0.18915246 | G8: =(F8/'Yearly GDP'!$B$2)*100 -> 36.732913 | H8: =(K8/I8) -> 0.8076614 | I8: =(J8/L8)*100 -> 6.4061499 | J8: =L8/O8 -> 90.78155 | K8: 5.174 | L8: 1417.1 | M8: 3.05 | N8: =K8-I8 -> -1.2321499 | O8: 15.61 | P8: 3.94 | Q8: =K8-P8 -> 1.234 | R8: 93.2 | S8: =(O8*T8) -> 70.5572 | T8: 4.52
A9: 8 | B9: 37895 | C9: 926748 | D9: =C9/E9 -> 20448.985 | E9: 45.32 | F9: =(D9/100000) -> 0.20448985 | G9: =(F9/'Yearly GDP'!$B$2)*100 -> 39.711394 | H9: =(K9/I9) -> 0.87465 | I9: =(J9/L9)*100 -> 5.8309038 | J9: =L9/O9 -> 90.723032 | K9: 5.1 | L9: 1555.9 | M9: 3.35 | N9: =K9-I9 -> -0.73090379 | O9: 17.15 | P9: 4.297 | Q9: =K9-P9 -> 0.803 | R9: 92.88 | S9: =(O9*T9) -> 78.0325 | T9: 4.55
A10: 9 | B10: 37926 | C10: 979541 | D10: =C10/E10 -> 21401.376 | E10: 45.77 | F10: =(D10/100000) -> 0.21401376 | G10: =(F10/'Yearly GDP'!$B$2)*100 -> 41.560913 | H10: =(K10/I10) -> 0.9166807 | I10: =(J10/L10)*100 -> 5.6148231 | J10: =L10/O10 -> 90.693431 | K10: 5.147 | L10: 1615.25 | M10: 3.47 | N10: =K10-I10 -> -0.46782313 | O10: 17.81 | P10: 4.334 | Q10: =K10-P10 -> 0.813 | R10: 90.28 | S10: =(O10*T10) -> 75.6925 | T10: 4.25
A11: 10 | B11: 37956 | C11: 1167029 | D11: =C11/E11 -> 25578.718 | E11: 45.625 | F11: =(D11/100000) -> 0.25578718 | G11: =(F11/'Yearly GDP'!$B$2)*100 -> 49.6732 | H11: =(K11/I11) -> 1.0617906 | I11: =(J11/L11)*100 -> 4.8239267 | J11: =L11/O11 -> 90.677762 | K11: 5.122 | L11: 1879.75 | M11: 4.05 | N11: =K11-I11 -> 0.29807332 | O11: 20.73 | P11: 4.253 | Q11: =K11-P11 -> 0.869 | R11: 87.26 | S11: =(O11*T11) -> 87.8952 | T11: 4.24
A12: 11 | B12: 37987 | C12: 1116150 | D12: =C12/E12 -> 24655.401 | E12: 45.27 | F12: =(D12/100000) -> 0.24655401 | G12: =(F12/'Yearly GDP'!$B$3)*100 -> 40.571665 | H12: =(K12/I12) -> 1.0395168 | I12: =(J12/L12)*100 -> 5.01002 | J12: =L12/O12 -> 90.668838 | K12: 5.208 | L12: 1809.75 | M12: 3.9 | N12: =K12-I12 -> 0.19797996 | O12: 19.96 | P12: 4.134 | Q12: =K12-P12 -> 1.074 | R12: 87.42 | S12: =(O12*T12) -> 86.4268 | T12: 4.33
A13: 12 | B13: 38018 | C13: 1110954 | D13: =C13/E13 -> 24575.91 | E13: 45.205 | F13: =(D13/100000) -> 0.2457591 | G13: =(F13/'Yearly GDP'!$B$3)*100 -> 40.440859 | H13: =(K13/I13) -> 1.039311 | I13: =(J13/L13)*100 -> 5.0658561 | J13: =L13/O13 -> 91.200608 | K13: 5.265 | L13: 1800.3 | M13: 3.89 | N13: =K13-I13 -> 0.19914387 | O13: 19.74 | P13: 3.972 | Q13: =K13-P13 -> 1.293 | R13: 87.42 | S13: =(O13*T13) -> 85.4742 | T13: 4.33
A14: 13 | B14: 38047 | C14: 1120976 | D14: =C14/E14 -> 25858.731 | E14: 43.35 | F14: =(D14/100000) -> 0.25858731 | G14: =(F14/'Yearly GDP'!$B$3)*100 -> 42.551804 | H14: =(K14/I14) -> 1.065429 | I14: =(J14/L14)*100 -> 4.8309179 | J14: =L14/O14 -> 85.599034 | K14: 5.147 | L14: 1771.9 | M14: 3.5 | N14: =K14-I14 -> 0.31608213 | O14: 20.7 | P14: 3.837 | Q14: =K14-P14 -> 1.31 | R14: 87.95 | S14: =(O14*T14) -> 88.596 | T14: 4.28
A15: 14 | B15: 38078 | C15: 1171828 | D15: =C15/E15 -> 26350.978 | E15: 44.47 | F15: =(D15/100000) -> 0.26350978 | G15: =(F15/'Yearly GDP'!$B$3)*100 -> 43.36182 | H15: =(K15/I15) -> 0.9558556 | I15: =(J15/L15)*100 -> 5.3533191 | J15: =L15/O15 -> 96.150964 | K15: 5.117 | L15: 1796.1 | M15: 3.54 | N15: =K15-I15 -> -0.23631906 | O15: 18.68 | P15: 4.51 | Q15: =K15-P15 -> 0.607 | R15: 90.68 | S15: =(O15*T15) -> 81.258 | T15: 4.35
A16: 15 | B16: 38108 | C16: 950494 | D16: =C16/E16 -> 20899.164 | E16: 45.48 | F16: =(D16/100000) -> 0.20899164 | G16: =(F16/'Yearly GDP'!$B$3)*100 -> 34.390595 | H16: =(K16/I16) -> 0.6297156 | I16: =(J16/L16)*100 -> 8.3752094 | J16: =L16/O16 -> 124.25461 | K16: 5.274 | L16: 1483.6 | M16: 2.84 | N16: =K16-I16 -> -3.1012094 | O16: 11.94 | P16: 4.665 | Q16: =K16-P16 -> 0.609 | R16: 88.98 | S16: =(O16*T16) -> 52.0584 | T16: 4.36
A17: 16 | B17: 38139 | C17: 979700 | D17: =C17/E17 -> 21309.407 | E17: 45.975 | F17: =(D17/100000) -> 0.21309407 | G17: =(F17/'Yearly GDP'!$B$3)*100 -> 35.065669 | H17: =(K17/I17) -> 0.73944 | I17: =(J17/L17)*100 -> 7.9113924 | J17: =L17/O17 -> 119.11392 | K17: 5.85 | L17: 1505.6 | M17: 2.83 | N17: =K17-I17 -> -2.0613924 | O17: 12.64 | P17: 4.583 | Q17: =K17-P17 -> 1.267 | R17: 89 | S17: =(O17*T17) -> 56.248 | T17: 4.45
A18: 17 | B18: 38169 | C18: 1066087 | D18: =C18/E18 -> 22988.399 | E18: 46.375 | F18: =(D18/100000) -> 0.22988399 | G18: =(F18/'Yearly GDP'!$B$3)*100 -> 37.828532 | H18: =(K18/I18) -> 0.8401532 | I18: =(J18/L18)*100 -> 7.3367572 | J18: =L18/O18 -> 119.75789 | K18: 6.164 | L18: 1632.3 | M18: 2.95 | N18: =K18-I18 -> -1.1727572 | O18: 13.63 | P18: 4.491 | Q18: =K18-P18 -> 1.673 | R18: 90.11 | S18: =(O18*T18) -> 59.5631 | T18: 4.37
A19: 18 | B19: 38200 | C19: 1143074.9 | D19: =C19/E19 -> 24680.447 | E19: 46.315 | F19: =(D19/100000) -> 0.24680447 | G19: =(F19/'Yearly GDP'!$B$3)*100 -> 40.61288 | H19: =(K19/I19) -> 0.8305396 | I19: =(J19/L19)*100 -> 7.3313783 | J19: =L19/O19 -> 119.62977 | K19: 6.089 | L19: 1631.75 | M19: 2.95 | N19: =K19-I19 -> -1.2423783 | O19: 13.64 | P19: 4.24 | Q19: =K19-P19 -> 1.849 | R19: 88.96 | S19: =(O19*T19) -> 62.3348 | T19: 4.57
A20: 19 | B20: 38231 | C20: 1227550 | D20: =C20/E20 -> 26729.45 | E20: 45.925 | F20: =(D20/100000) -> 0.2672945 | G20: =(F20/'Yearly GDP'!$B$3)*100 -> 43.984614 | H20: =(K20/I20) -> 0.9109996 | I20: =(J20/L20)*100 -> 6.8540096 | J20: =L20/O20 -> 119.63674 | K20: 6.244 | L20: 1745.5 | M20: 3.16 | N20: =K20-I20 -> -0.6100096 | O20: 14.59 | P20: 4.123 | Q20: =K20-P20 -> 2.121 | R20: 87.51 | S20: =(O20*T20) -> 72.2205 | T20: 4.95
A21: 20 | B21: 38261 | C21: 1253825 | D21: =C21/E21 -> 27656.888 | E21: 45.335 | F21: =(D21/100000) -> 0.27656888 | G21: =(F21/'Yearly GDP'!$B$3)*100 -> 45.510758 | H21: =(K21/I21) -> 1.0243473 | I21: =(J21/L21)*100 -> 6.6979236 | J21: =L21/O21 -> 119.6852 | K21: 6.861 | L21: 1786.9 | M21: 3.08 | N21: =K21-I21 -> 0.16307636 | O21: 14.93 | P21: 4.029 | Q21: =K21-P21 -> 2.832 | R21: 84.98 | S21: =(O21*T21) -> 79.129 | T21: 5.3
A22: 21 | B22: 38292 | C22: 1446292 | D22: =C22/E22 -> 32500.944 | E22: 44.5 | F22: =(D22/100000) -> 0.32500944 | G22: =(F22/'Yearly GDP'!$B$3)*100 -> 53.481889 | H22: =(K22/I22) -> 1.1795883 | I22: =(J22/L22)*100 -> 6.1012813 | J22: =L22/O22 -> 119.5119 | K22: 7.197 | L22: 1958.8 | M22: 3.38 | N22: =K22-I22 -> 1.0957187 | O22: 16.39 | P22: 4.355 | Q22: =K22-P22 -> 2.842 | R22: 81.82 | S22: =(O22*T22) -> 85.228 | T22: 5.2
A23: 22 | B23: 38322 | C23: 1579161 | D23: =C23/E23 -> 36512.393 | E23: 43.25 | F23: =(D23/100000) -> 0.36512393 | G23: =(F23/'Yearly GDP'!$B$3)*100 -> 60.082924 | H23: =(K23/I23) -> 1.0273592 | I23: =(J23/L23)*100 -> 6.5274151 | J23: =L23/O23 -> 135.80287 | K23: 6.706 | L23: 2080.5 | M23: 3.61 | N23: =K23-I23 -> 0.17858486 | O23: 15.32 | P23: 4.222 | Q23: =K23-P23 -> 2.484 | R23: 81 | S23: =(O23*T23) -> 81.196 | T23: 5.3
A24: 23 | B24: 38353 | C24: 1557444 | D24: =C24/E24 -> 35684.362 | E24: 43.645 | F24: =(D24/100000) -> 0.35684362 | G24: =(F24/'Yearly GDP'!$B$4)*100 -> 50.319908 | H24: =(K24/I24) -> 0.9840004 | I24: =(J24/L24)*100 -> 6.8119891 | J24: =L24/O24 -> 140.16349 | K24: 6.703 | L24: 2057.6 | M24: 3.57 | N24: =K24-I24 -> -0.1089891 | O24: 14.68 | P24: 4.132 | Q24: =K24-P24 -> 2.571 | R24: 83.64 | S24: =(O24*T24) -> 76.336 | T24: 5.2
A25: 24 | B25: 38384 | C25: 1614597 | D25: =C25/E25 -> 37002.338 | E25: 43.635 | F25: =(D25/100000) -> 0.37002338 | G25: =(F25/'Yearly GDP'!$B$4)*100 -> 52.178436 | H25: =(K25/I25) -> 0.9836598 | I25: =(J25/L25)*100 -> 6.6577896 | J25: =L25/O25 -> 140.02996 | K25: 6.549 | L25: 2103.25 | M25: 3.92 | N25: =K25-I25 -> -0.10878961 | O25: 15.02 | P25: 4.381 | Q25: =K25-P25 -> 2.168 | R25: 82.51 | S25: =(O25*T25) -> 78.104 | T25: 5.2
A26: 25 | B26: 38412 | C26: 1585585 | D26: =C26/E26 -> 36304.179 | E26: 43.675 | F26: =(D26/100000) -> 0.36304179 | G26: =(F26/'Yearly GDP'!$B$4)*100 -> 51.193934 | H26: =(K26/I26) -> 0.974696 | I26: =(J26/L26)*100 -> 6.8493151 | J26: =L26/O26 -> 139.42808 | K26: 6.676 | L26: 2035.65 | M26: 3.82 | N26: =K26-I26 -> -0.17331507 | O26: 14.6 | P26: 4.488 | Q26: =K26-P26 -> 2.188 | R26: 84.05 | S26: =(O26*T26) -> 76.65 | T26: 5.25
A27: 26 | B27: 38443 | C27: 1517908 | D27: =C27/E27 -> 34950.679 | E27: 43.43 | F27: =(D27/100000) -> 0.34950679 | G27: =(F27/'Yearly GDP'!$B$4)*100 -> 49.285312 | H27: =(K27/I27) -> 0.9606153 | I27: =(J27/L27)*100 -> 7.535795 | J27: =L27/O27 -> 143.3685 | K27: 7.239 | L27: 1902.5 | M27: 3.56 | N27: =K27-I27 -> -0.29679503 | O27: 13.27 | P27: 4.2 | Q27: =K27-P27 -> 3.039 | R27: 84.42 | S27: =(O27*T27) -> 70.331 | T27: 5.3 | U27: 980.57 | Y27: 994.01
A28: 27 | B28: 38473 | C28: 1654994.9 | D28: =C28/E28 -> 37871.737 | E28: 43.7 | F28: =(D28/100000) -> 0.37871737 | G28: =(F28/'Yearly GDP'!$B$4)*100 -> 53.404409 | H28: =(K28/I28) -> 0.9728726 | I28: =(J28/L28)*100 -> 7.1736011 | J28: =L28/O28 -> 149.75251 | K28: 6.979 | L28: 2087.55 | M28: 3.91 | N28: =K28-I28 -> -0.19460115 | O28: 13.94 | P28: 3.987 | Q28: =K28-P28 -> 2.992 | R28: 87.8 | S28: =(O28*T28) -> 72.488 | T28: 5.2 | U28: 1054.85 | Y28: 1108.69
A29: 28 | B29: 38504 | C29: 1727502 | D29: =C29/E29 -> 39726.388 | E29: 43.485 | F29: =(D29/100000) -> 0.39726388 | G29: =(F29/'Yearly GDP'!$B$4)*100 -> 56.019726 | H29: =(K29/I29) -> 0.9883917 | I29: =(J29/L29)*100 -> 6.9881202 | J29: =L29/O29 -> 155.1782 | K29: 6.907 | L29: 2220.6 | M29: 3.98 | N29: =K29-I29 -> -0.081120196 | O29: 14.31 | P29: 3.921 | Q29: =K29-P29 -> 2.986 | R29: 88.98 | S29: =(O29*T29) -> 77.274 | T29: 5.4 | U29: 1064.61 | Y29: 1122.95
A30: 29 | B30: 38534 | C30: 1848740 | D30: =C30/E30 -> 42558.471 | E30: 43.44 | F30: =(D30/100000) -> 0.42558471 | G30: =(F30/'Yearly GDP'!$B$4)*100 -> 60.013356 | H30: =(K30/I30) -> 0.98136 | I30: =(J30/L30)*100 -> 7.0921986 | J30: =L30/O30 -> 163.99291 | K30: 6.96 | L30: 2312.3 | M30: 3.86 | N30: =K30-I30 -> -0.13219858 | O30: 14.1 | P30: 4.282 | Q30: =K30-P30 -> 2.678 | R30: 89.23 | S30: =(O30*T30) -> 74.73 | T30: 5.3 | U30: 1179.61 | Y30: 1255.36
A31: 30 | B31: 38565 | C31: 1957491 | D31: =C31/E31 -> 44473.27 | E31: 44.015 | F31: =(D31/100000) -> 0.4447327 | G31: =(F31/'Yearly GDP'!$B$4)*100 -> 62.713489 | H31: =(K31/I31) -> 1.0484932 | I31: =(J31/L31)*100 -> 6.7658999 | J31: =L31/O31 -> 161.34303 | K31: 7.094 | L31: 2384.65 | M31: 3.89 | N31: =K31-I31 -> 0.32810014 | O31: 14.78 | P31: 4.014 | Q31: =K31-P31 -> 3.08 | R31: 87.54 | S31: =(O31*T31) -> 76.856 | T31: 5.2 | U31: 1287.87 | Y31: 1465.98
A32: 31 | B32: 38596 | C32: 2098263 | D32: =C32/E32 -> 47736.617 | E32: 43.955 | F32: =(D32/100000) -> 0.47736617 | G32: =(F32/'Yearly GDP'!$B$4)*100 -> 67.315261 | H32: =(K32/I32) -> 1.1468115 | I32: =(J32/L32)*100 -> 6.1919505 | J32: =L32/O32 -> 161.0774 | K32: 7.101 | L32: 2601.4 | M32: 4.01 | N32: =K32-I32 -> 0.90904954 | O32: 16.15 | P32: 4.332 | Q32: =K32-P32 -> 2.769 | R32: 89.35 | S32: =(O32*T32) -> 86.241 | T32: 5.34 | U32: 1337.5 | Y32: 1463.97
A33: 32 | B33: 38626 | C33: 1927645 | D33: =C33/E33 -> 42770.024 | E33: 45.07 | F33: =(D33/100000) -> 0.42770024 | G33: =(F33/'Yearly GDP'!$B$4)*100 -> 60.311675 | H33: =(K33/I33) -> 1.0101877 | I33: =(J33/L33)*100 -> 7.0274069 | J33: =L33/O33 -> 166.6163 | K33: 7.099 | L33: 2370.95 | M33: 3.63 | N33: =K33-I33 -> 0.071593113 | O33: 14.23 | P33: 4.557 | Q33: =K33-P33 -> 2.542 | R33: 89.93 | S33: =(O33*T33) -> 78.6919 | T33: 5.53 | U33: 1214.03 | Y33: 1299.93
A34: 33 | B34: 38657 | C34: 2166823 | D34: =C34/E34 -> 47217.76 | E34: 45.89 | F34: =(D34/100000) -> 0.4721776 | G34: =(F34/'Yearly GDP'!$B$4)*100 -> 66.5836 | H34: =(K34/I34) -> 1.1297385 | I34: =(J34/L34)*100 -> 6.2695925 | J34: =L34/O34 -> 166.28527 | K34: 7.083 | L34: 2652.25 | M34: 4.06 | N34: =K34-I34 -> 0.81340752 | O34: 15.95 | P34: 4.49 | Q34: =K34-P34 -> 2.593 | R34: 91.51 | S34: =(O34*T34) -> 91.7125 | T34: 5.75 | U34: 1331.69 | Y34: 1455.22
A35: 34 | B35: 38687 | C35: 2322392 | D35: =C35/E35 -> 51614.446 | E35: 44.995 | F35: =(D35/100000) -> 0.51614446 | G35: =(F35/'Yearly GDP'!$B$4)*100 -> 72.783538 | H35: =(K35/I35) -> 1.220076 | I35: =(J35/L35)*100 -> 5.8275058 | J35: =L35/O35 -> 165.30012 | K35: 7.11 | L35: 2836.55 | M35: 4.37 | N35: =K35-I35 -> 1.2824942 | O35: 17.16 | P35: 4.395 | Q35: =K35-P35 -> 2.715 | R35: 90.96 | S35: =(O35*T35) -> 104.3328 | T35: 6.08 | U35: 1414.17 | Y35: 1537.75
A36: 35 | B36: 38718 | C36: 2434395 | D36: =C36/E36 -> 55421.628 | E36: 43.925 | F36: =(D36/100000) -> 0.55421628 | G36: =(F36/'Yearly GDP'!$B$5)*100 -> 67.556044 | H36: =(K36/I36) -> 1.319588 | I36: =(J36/L36)*100 -> 5.5865922 | J36: =L36/O36 -> 167.65922 | K36: 7.372 | L36: 3001.1 | M36: 4.53 | N36: =K36-I36 -> 1.7854078 | O36: 17.9 | P36: 4.519 | Q36: =K36-P36 -> 2.853 | R36: 88.81 | S36: =(O36*T36) -> 118.498 | T36: 6.62 | U36: 1511.78 | Y36: 1615.59
A37: 36 | B37: 38749 | C37: 2512083 | D37: =C37/E37 -> 56738.182 | E37: 44.275 | F37: =(D37/100000) -> 0.56738182 | G37: =(F37/'Yearly GDP'!$B$5)*100 -> 69.160855 | H37: =(K37/I37) -> 1.3507011 | I37: =(J37/L37)*100 -> 5.4734537 | J37: =L37/O37 -> 168.29228 | K37: 7.393 | L37: 3074.7 | M37: 4.64 | N37: =K37-I37 -> 1.9195463 | O37: 18.27 | P37: 4.557 | Q37: =K37-P37 -> 2.836 | R37: 90.08 | S37: =(O37*T37) -> 121.3128 | T37: 6.64 | U37: 1548.68 | Y37: 1601.12
A38: 37 | B38: 38777 | C38: 2813201 | D38: =C38/E38 -> 63218 | E38: 44.5 | F38: =(D38/100000) -> 0.63218 | G38: =(F38/'Yearly GDP'!$B$5)*100 -> 77.059411 | H38: =(K38/I38) -> 1.52963 | I38: =(J38/L38)*100 -> 4.9358342 | J38: =L38/O38 -> 167.94423 | K38: 7.55 | L38: 3402.55 | M38: 5.15 | N38: =K38-I38 -> 2.6141658 | O38: 20.26 | P38: 4.853 | Q38: =K38-P38 -> 2.697 | R38: 89.39 | S38: =(O38*T38) -> 123.586 | T38: 6.1 | U38: 1721.36 | Y38: 1762.19
A39: 38 | B39: 38808 | C39: 2990200 | D39: =C39/E39 -> 66596.882 | E39: 44.9 | F39: =(D39/100000) -> 0.66596882 | G39: =(F39/'Yearly GDP'!$B$5)*100 -> 81.178091 | H39: =(K39/I39) -> 1.500909 | I39: =(J39/L39)*100 -> 4.9236829 | J39: =L39/O39 -> 175.16494 | K39: 7.39 | L39: 3557.6 | M39: 5.39 | N39: =K39-I39 -> 2.4663171 | O39: 20.31 | P39: 5.057 | Q39: =K39-P39 -> 2.333 | R39: 85.88 | S39: =(O39*T39) -> 110.8926 | T39: 5.46 | U39: 1846.28 | Y39: 1977.06
A40: 39 | B40: 38838 | C40: 2612639 | D40: =C40/E40 -> 56422.395 | E40: 46.305 | F40: =(D40/100000) -> 0.56422395 | G40: =(F40/'Yearly GDP'!$B$5)*100 -> 68.775927 | H40: =(K40/I40) -> 1.3372614 | I40: =(J40/L40)*100 -> 5.7273769 | J40: =L40/O40 -> 175.89061 | K40: 7.659 | L40: 3071.05 | M40: 4.57 | N40: =K40-I40 -> 1.9316231 | O40: 17.46 | P40: 5.123 | Q40: =K40-P40 -> 2.536 | R40: 84.65 | S40: =(O40*T40) -> 100.7442 | T40: 5.77 | U40: 1568.17 | Y40: 1814.58
...

Sheet Daily
A1: S.no | B1: Date | C1: Market Cap | D1: US $ | E1: USD/INR | F1: Trillion | G1: Market Cap to GDP | H1: BEER | I1: Nifty 50 Earning Yield | J1: NIFTY 50 EPS | K1: India 10Yr Yield | L1: Nifty 50 | M1: Price to Book | N1: Equity Earnings Yield vs 10 Year G Sec Yield Gap | O1: Nifty 50 pe | P1: US 10yr Bond | Q1: India yr- US 10yr | R1: Dollar index | S1: PREITY Ratio | T1: 91 day T Bill | U1: Nifty Midcap 150 | V1: Midcap 150 PE | W1: Midcap EPS | X1: Midcap Earning Yield | Y1: Nifty Smallcap 250 | Z1: Smallcap 250 PE | AA1: Smallcap EPS | AB1: Smallcap Earning Yield
A2: 1 | B2: 37683 | C2: 582058 | D2: =C2/E2 -> 12220.407 | E2: 47.63 | F2: =(D2/100000) -> 0.12220407 | G2: =(F2/'Yearly GDP'!$B$2)*100 -> 23.731711 | H2: =(K2/I2) -> 0.878114 | I2: =(J2/L2)*100 -> 6.9637883 | J2: =L2/O2 -> 73.736072 | K2: 6.115 | L2: 1058.85 | M2: 2.32 | N2: =K2-I2 -> -0.8487883 | O2: 14.36 | P2: 3.675 | Q2: =K2-P2 -> 2.44 | R2: 99.18 | S2: =(O2*T2) -> 77.544 | T2: 5.4
A3: 2 | B3: 37684 | C3: 575406 | D3: =C3/E3 -> 12075.677 | E3: 47.65 | F3: =(D3/100000) -> 0.12075677 | G3: =(F3/'Yearly GDP'!$B$2)*100 -> 23.450648 | H3: =(K3/I3) -> 0.883592 | I3: =(J3/L3)*100 -> 7.0224719 | J3: =L3/O3 -> 73.497191 | K3: 6.205 | L3: 1046.6 | M3: 2.3 | N3: =K3-I3 -> -0.81747191 | O3: 14.24 | P3: 3.648 | Q3: =K3-P3 -> 2.557 | R3: 99.16 | S3: =(O3*T3) -> 75.472 | T3: 5.3
A4: 3 | B4: 37685 | C4: 571902 | D4: =C4/E4 -> 12002.141 | E4: 47.65 | F4: =(D4/100000) -> 0.12002141 | G4: =(F4/'Yearly GDP'!$B$2)*100 -> 23.307843 | H4: =(K4/I4) -> 0.8908056 | I4: =(J4/L4)*100 -> 7.0621469 | J4: =L4/O4 -> 73.495763 | K4: 6.291 | L4: 1040.7 | M4: 2.28 | N4: =K4-I4 -> -0.77114689 | O4: 14.16 | P4: 3.631 | Q4: =K4-P4 -> 2.66 | R4: 98.29 | S4: =(O4*T4) -> 76.464 | T4: 5.4
A5: 4 | B5: 37686 | C5: 567021 | D5: =C5/E5 -> 11917.213 | E5: 47.58 | F5: =(D5/100000) -> 0.11917213 | G5: =(F5/'Yearly GDP'!$B$2)*100 -> 23.142916 | H5: =(K5/I5) -> 0.8756123 | I5: =(J5/L5)*100 -> 7.1275837 | J5: =L5/O5 -> 73.503207 | K5: 6.241 | L5: 1031.25 | M5: 2.26 | N5: =K5-I5 -> -0.88658375 | O5: 14.03 | P5: 3.654 | Q5: =K5-P5 -> 2.587 | R5: 98.37 | S5: =(O5*T5) -> 76.4635 | T5: 5.45
A6: 5 | B6: 37687 | C6: 558089 | D6: =C6/E6 -> 11712.256 | E6: 47.65 | F6: =(D6/100000) -> 0.11712256 | G6: =(F6/'Yearly GDP'!$B$2)*100 -> 22.744895 | H6: =(K6/I6) -> 0.88922 | I6: =(J6/L6)*100 -> 7.2254335 | J6: =L6/O6 -> 73.489884 | K6: 6.425 | L6: 1017.1 | M6: 2.23 | N6: =K6-I6 -> -0.80043353 | O6: 13.84 | P6: 3.644 | Q6: =K6-P6 -> 2.781 | R6: 98.1 | S6: =(O6*T6) -> 78.196 | T6: 5.65
A7: 6 | B7: 37690 | C7: 552012.05 | D7: =C7/E7 -> 11584.723 | E7: 47.65 | F7: =(D7/100000) -> 0.11584723 | G7: =(F7/'Yearly GDP'!$B$2)*100 -> 22.497229 | H7: =(K7/I7) -> 0.887623 | I7: =(J7/L7)*100 -> 7.2992701 | J7: =L7/O7 -> 73.481752 | K7: 6.479 | L7: 1006.7 | M7: 2.21 | N7: =K7-I7 -> -0.82027007 | O7: 13.7 | P7: 3.564 | Q7: =K7-P7 -> 2.915 | R7: 97.92 | S7: =(O7*T7) -> 78.09 | T7: 5.7
A8: 7 | B8: 37691 | C8: 555359 | D8: =C8/E8 -> 11669.657 | E8: 47.59 | F8: =(D8/100000) -> 0.11669657 | G8: =(F8/'Yearly GDP'!$B$2)*100 -> 22.662169 | H8: =(K8/I8) -> 0.8857734 | I8: =(J8/L8)*100 -> 7.2411296 | J8: =L8/O8 -> 73.464881 | K8: 6.414 | L8: 1014.55 | M8: 2.23 | N8: =K8-I8 -> -0.82712962 | O8: 13.81 | P8: 3.582 | Q8: =K8-P8 -> 2.832 | R8: 98.08 | S8: =(O8*T8) -> 78.717 | T8: 5.7
A9: 8 | B9: 37692 | C9: 551150 | D9: =C9/E9 -> 11578.782 | E9: 47.6 | F9: =(D9/100000) -> 0.11578782 | G9: =(F9/'Yearly GDP'!$B$2)*100 -> 22.485691 | H9: =(K9/I9) -> 0.8671406 | I9: =(J9/L9)*100 -> 7.3367572 | J9: =L9/O9 -> 73.492296 | K9: 6.362 | L9: 1001.7 | M9: 2.2 | N9: =K9-I9 -> -0.97475715 | O9: 13.63 | P9: 3.586 | Q9: =K9-P9 -> 2.776 | R9: 98.19 | S9: =(O9*T9) -> 80.417 | T9: 5.9
A10: 9 | B10: 37693 | C10: 549801 | D10: =C10/E10 -> 11548.015 | E10: 47.61 | F10: =(D10/100000) -> 0.11548015 | G10: =(F10/'Yearly GDP'!$B$2)*100 -> 22.425943 | H10: =(K10/I10) -> 0.866728 | I10: =(J10/L10)*100 -> 7.3529412 | J10: =L10/O10 -> 73.503676 | K10: 6.373 | L10: 999.65 | M10: 2.19 | N10: =K10-I10 -> -0.97994118 | O10: 13.6 | P10: 3.75 | Q10: =K10-P10 -> 2.623 | R10: 99.61 | S10: =(O10*T10) -> 78.88 | T10: 5.8
A11: 10 | B11: 37697 | C11: 546264 | D11: =C11/E11 -> 11468.906 | E11: 47.63 | F11: =(D11/100000) -> 0.11468906 | G11: =(F11/'Yearly GDP'!$B$2)*100 -> 22.272316 | H11: =(K11/I11) -> 0.8732864 | I11: =(J11/L11)*100 -> 7.4019245 | J11: =L11/O11 -> 73.50111 | K11: 6.464 | L11: 993 | M11: 2.18 | N11: =K11-I11 -> -0.9379245 | O11: 13.51 | P11: 3.84 | Q11: =K11-P11 -> 2.624 | R11: 99.69 | S11: =(O11*T11) -> 77.007 | T11: 5.7
A12: 11 | B12: 37699 | C12: 549929 | D12: =C12/E12 -> 11541.007 | E12: 47.65 | F12: =(D12/100000) -> 0.11541007 | G12: =(F12/'Yearly GDP'!$B$2)*100 -> 22.412334 | H12: =(K12/I12) -> 0.8852547 | I12: =(J12/L12)*100 -> 7.293946 | J12: =L12/O12 -> 73.223924 | K12: 6.457 | L12: 1003.9 | M12: 2.2 | N12: =K12-I12 -> -0.83694602 | O12: 13.71 | P12: 3.986 | Q12: =K12-P12 -> 2.471 | R12: 102.11 | S12: =(O12*T12) -> 80.2035 | T12: 5.85
A13: 12 | B13: 37700 | C13: 558210 | D13: =C13/E13 -> 11702.516 | E13: 47.7 | F13: =(D13/100000) -> 0.11702516 | G13: =(F13/'Yearly GDP'!$B$2)*100 -> 22.725979 | H13: =(K13/I13) -> 0.903 | I13: =(J13/L13)*100 -> 7.1428571 | J13: =L13/O13 -> 73.232143 | K13: 6.45 | L13: 1025.25 | M13: 2.25 | N13: =K13-I13 -> -0.69285714 | O13: 14 | P13: 3.955 | Q13: =K13-P13 -> 2.495 | R13: 101.63 | S13: =(O13*T13) -> 81.9 | T13: 5.85
... A212: 211 | B212: 37986 | C212: 1167029 | D212: =C212/E212 -> 25578.718 | E212: 45.625 | F212: =(D212/100000) -> 0.25578718 | G212: =(F212/'Yearly GDP'!$B$2)*100 -> 49.6732 | H212: =(K212/I212) -> 1.0617906 | I212: =(J212/L212)*100 -> 4.8239267 | J212: =L212/O212 -> 90.677762 | K212: 5.122 | L212: 1879.75 | M212: 4.05 | N212: =K212-I212 -> 0.29807332 | O212: 20.73 | P212: 4.253 | Q212: =K212-P212 -> 0.869 | R212: 87.26 | S212: =(O212*T212) -> 87.8952 | T212: 4.24
A213: 212 | B213: 37987 | C213: 1190885 | D213: =C213/E213 -> 26118.19 | E213: 45.596 | F213: =(D213/100000) -> 0.2611819 | G213: =(F213/'Yearly GDP'!$B$3)*100 -> 42.978756 | H213: =(K213/I213) -> 1.0812843 | I213: =(J213/L213)*100 -> 4.7415837 | J213: =L213/O213 -> 90.670934 | K213: 5.127 | L213: 1912.25 | M213: 4.12 | N213: =K213-I213 -> 0.38541631 | O213: 21.09 | P213: 4.253 | Q213: =K213-P213 -> 0.874 | R213: 87.26 | S213: =(O213*T213) -> 88.7889 | T213: 4.21
A214: 213 | B214: 37988 | C214: 1225500 | D214: =C214/E214 -> 26851.446 | E214: 45.64 | F214: =(D214/100000) -> 0.26851446 | G214: =(F214/'Yearly GDP'!$B$3)*100 -> 44.185365 | H214: =(K214/I214) -> 1.0989666 | I214: =(J214/L214)*100 -> 4.6598322 | J214: =L214/O214 -> 90.682665 | K214: 5.121 | L214: 1946.05 | M214: 4.19 | N214: =K214-I214 -> 0.46116775 | O214: 21.46 | P214: 4.374 | Q214: =K214-P214 -> 0.747 | R214: 86.93 | S214: =(O214*T214) -> 90.5612 | T214: 4.22
A215: 214 | B215: 37991 | C215: 1230103 | D215: =C215/E215 -> 26981.86 | E215: 45.59 | F215: =(D215/100000) -> 0.2698186 | G215: =(F215/'Yearly GDP'!$B$3)*100 -> 44.399967 | H215: =(K215/I215) -> 1.103872 | I215: =(J215/L215)*100 -> 4.6382189 | J215: =L215/O215 -> 90.67718 | K215: 5.12 | L215: 1955 | M215: 4.21 | N215: =K215-I215 -> 0.48178108 | O215: 21.56 | P215: 4.38 | Q215: =K215-P215 -> 0.74 | R215: 86.35 | S215: =(O215*T215) -> 89.6896 | T215: 4.16
A216: 215 | B216: 37992 | C216: 1207632 | D216: =C216/E216 -> 26474.449 | E216: 45.615 | F216: =(D216/100000) -> 0.26474449 | G216: =(F216/'Yearly GDP'!$B$3)*100 -> 43.564998 | H216: =(K216/I216) -> 1.08715 | I216: =(J216/L216)*100 -> 4.7058824 | J216: =L216/O216 -> 90.668235 | K216: 5.116 | L216: 1926.7 | M216: 4.15 | N216: =K216-I216 -> 0.41011765 | O216: 21.25 | P216: 4.274 | Q216: =K216-P216 -> 0.842 | R216: 85.93 | S216: =(O216*T216) -> 88.4 | T216: 4.16
A217: 216 | B217: 37993 | C217: 1201998 | D217: =C217/E217 -> 26397.233 | E217: 45.535 | F217: =(D217/100000) -> 0.26397233 | G217: =(F217/'Yearly GDP'!$B$3)*100 -> 43.437935 | H217: =(K217/I217) -> 1.0821566 | I217: =(J217/L217)*100 -> 4.730369 | J217: =L217/O217 -> 90.669347 | K217: 5.119 | L217: 1916.75 | M217: 4.12 | N217: =K217-I217 -> 0.38863103 | O217: 21.14 | P217: 4.245 | Q217: =K217-P217 -> 0.874 | R217: 86.52 | S217: =(O217*T217) -> 89.6336 | T217: 4.24
A218: 217 | B218: 37994 | C218: 1242777 | D218: =C218/E218 -> 27310.779 | E218: 45.505 | F218: =(D218/100000) -> 0.27310779 | G218: =(F218/'Yearly GDP'!$B$3)*100 -> 44.941219 | H218: =(K218/I218) -> 1.1100323 | I218: =(J218/L218)*100 -> 4.6061723 | J218: =L218/O218 -> 90.674804 | K218: 5.113 | L218: 1968.55 | M218: 4.24 | N218: =K218-I218 -> 0.50682773 | O218: 21.71 | P218: 4.269 | Q218: =K218-P218 -> 0.844 | R218: 85.88 | S218: =(O218*T218) -> 91.6162 | T218: 4.22
A219: 218 | B219: 37995 | C219: 1241569 | D219: =C219/E219 -> 27329.276 | E219: 45.43 | F219: =(D219/100000) -> 0.27329276 | G219: =(F219/'Yearly GDP'!$B$3)*100 -> 44.971657 | H219: =(K219/I219) -> 1.113165 | I219: =(J219/L219)*100 -> 4.5977011 | J219: =L219/O219 -> 90.662069 | K219: 5.118 | L219: 1971.9 | M219: 4.24 | N219: =K219-I219 -> 0.52029885 | O219: 21.75 | P219: 4.084 | Q219: =K219-P219 -> 1.034 | R219: 85.39 | S219: =(O219*T219) -> 91.785 | T219: 4.22
A220: 219 | B220: 37998 | C220: 1222453 | D220: =C220/E220 -> 26944.082 | E220: 45.37 | F220: =(D220/100000) -> 0.26944082 | G220: =(F220/'Yearly GDP'!$B$3)*100 -> 44.337802 | H220: =(K220/I220) -> 1.103044 | I220: =(J220/L220)*100 -> 4.6598322 | J220: =L220/O220 -> 90.661696 | K220: 5.14 | L220: 1945.6 | M220: 4.19 | N220: =K220-I220 -> 0.48016775 | O220: 21.46 | P220: 4.09 | Q220: =K220-P220 -> 1.05 | R220: 85.86 | S220: =(O220*T220) -> 90.7758 | T220: 4.23
A221: 220 | B221: 37999 | C221: 1225212 | D221: =C221/E221 -> 27016.803 | E221: 45.35 | F221: =(D221/100000) -> 0.27016803 | G221: =(F221/'Yearly GDP'!$B$3)*100 -> 44.457467 | H221: =(K221/I221) -> 1.1107248 | I221: =(J221/L221)*100 -> 4.6168052 | J221: =L221/O221 -> 90.655586 | K221: 5.128 | L221: 1963.6 | M221: 4.23 | N221: =K221-I221 -> 0.51119483 | O221: 21.66 | P221: 4.015 | Q221: =K221-P221 -> 1.113 | R221: 85.78 | S221: =(O221*T221) -> 91.4052 | T221: 4.22
A222: 221 | B222: 38000 | C222: 1235165.1 | D222: =C222/E222 -> 27224.269 | E222: 45.37 | F222: =(D222/100000) -> 0.27224269 | G222: =(F222/'Yearly GDP'!$B$3)*100 -> 44.798863 | H222: =(K222/I222) -> 1.1201064 | I222: =(J222/L222)*100 -> 4.5745654 | J222: =L222/O222 -> 90.674748 | K222: 5.124 | L222: 1982.15 | M222: 4.27 | N222: =K222-I222 -> 0.54943458 | O222: 21.86 | P222: 3.996 | Q222: =K222-P222 -> 1.128 | R222: 86.32 | S222: =(O222*T222) -> 92.6864 | T222: 4.24
A223: 222 | B223: 38001 | C223: 1218834 | D223: =C223/E223 -> 26828.836 | E223: 45.43 | F223: =(D223/100000) -> 0.26828836 | G223: =(F223/'Yearly GDP'!$B$3)*100 -> 44.148158 | H223: =(K223/I223) -> 1.1018016 | I223: =(J223/L223)*100 -> 4.6641791 | J223: =L223/O223 -> 90.692631 | K223: 5.139 | L223: 1944.45 | M223: 4.18 | N223: =K223-I223 -> 0.4748209 | O223: 21.44 | P223: 3.974 | Q223: =K223-P223 -> 1.165 | R223: 86.87 | S223: =(O223*T223) -> 91.3344 | T223: 4.26
A224: 223 | B224: 38002 | C224: 1187137 | D224: =C224/E224 -> 26148.392 | E224: 45.4 | F224: =(D224/100000) -> 0.26148392 | G224: =(F224/'Yearly GDP'!$B$3)*100 -> 43.028455 | H224: =(K224/I224) -> 1.0769248 | I224: =(J224/L224)*100 -> 4.7709924 | J224: =L224/O224 -> 90.679866 | K224: 5.138 | L224: 1900.65 | M224: 4.09 | N224: =K224-I224 -> 0.36700763 | O224: 20.96 | P224: 4.029 | Q224: =K224-P224 -> 1.109 | R224: 88.05 | S224: =(O224*T224) -> 88.6608 | T224: 4.23
... A464: 463 | B464: 38352 | C464: 1579161 | D464: =C464/E464 -> 36512.393 | E464: 43.25 | F464: =(D464/100000) -> 0.36512393 | G464: =(F464/'Yearly GDP'!$B$3)*100 -> 60.082924 | H464: =(K464/I464) -> 1.0273592 | I464: =(J464/L464)*100 -> 6.5274151 | J464: =L464/O464 -> 135.80287 | K464: 6.706 | L464: 2080.5 | M464: 3.61 | N464: =K464-I464 -> 0.17858486 | O464: 15.32 | P464: 4.222 | Q464: =K464-P464 -> 2.484 | R464: 81 | S464: =(O464*T464) -> 81.196 | T464: 5.3
A465: 464 | B465: 38355 | C465: 1605364 | D465: =C465/E465 -> 36989.954 | E465: 43.4 | F465: =(D465/100000) -> 0.36989954 | G465: =(F465/'Yearly GDP'!$B$4)*100 -> 52.160973 | H465: =(K465/I465) -> 1.0179666 | I465: =(J465/L465)*100 -> 6.4226076 | J465: =L465/O465 -> 135.83815 | K465: 6.538 | L465: 2115 | M465: 3.67 | N465: =K465-I465 -> 0.11539242 | O465: 15.57 | P465: 4.216 | Q465: =K465-P465 -> 2.322 | R465: 81.41 | S465: =(O465*T465) -> 79.407 | T465: 5.1
A466: 465 | B466: 38356 | C466: 1603244 | D466: =C466/E466 -> 36860.421 | E466: 43.495 | F466: =(D466/100000) -> 0.36860421 | G466: =(F466/'Yearly GDP'!$B$4)*100 -> 51.978313 | H466: =(K466/I466) -> 1.0045265 | I466: =(J466/L466)*100 -> 6.4557779 | J466: =L466/O466 -> 135.81343 | K466: 6.485 | L466: 2103.75 | M466: 3.65 | N466: =K466-I466 -> 0.029222079 | O466: 15.49 | P466: 4.295 | Q466: =K466-P466 -> 2.19 | R466: 82.7 | S466: =(O466*T466) -> 78.999 | T466: 5.1
A467: 466 | B467: 38357 | C467: 1548506.1 | D467: =C467/E467 -> 35573.308 | E467: 43.53 | F467: =(D467/100000) -> 0.35573308 | G467: =(F467/'Yearly GDP'!$B$4)*100 -> 50.163305 | H467: =(K467/I467) -> 0.9824232 | I467: =(J467/L467)*100 -> 6.684492 | J467: =L467/O467 -> 135.84225 | K467: 6.567 | L467: 2032.2 | M467: 3.52 | N467: =K467-I467 -> -0.11749198 | O467: 14.96 | P467: 4.287 | Q467: =K467-P467 -> 2.28 | R467: 82.65 | S467: =(O467*T467) -> 77.792 | T467: 5.2
A468: 467 | B468: 38358 | C468: 1523410.1 | D468: =C468/E468 -> 34721.598 | E468: 43.875 | F468: =(D468/100000) -> 0.34721598 | G468: =(F468/'Yearly GDP'!$B$4)*100 -> 48.962276 | H468: =(K468/I468) -> 0.9715955 | I468: =(J468/L468)*100 -> 6.7980965 | J468: =L468/O468 -> 135.84976 | K468: 6.605 | L468: 1998.35 | M468: 3.47 | N468: =K468-I468 -> -0.19309653 | O468: 14.71 | P468: 4.263 | Q468: =K468-P468 -> 2.342 | R468: 83.24 | S468: =(O468*T468) -> 75.7565 | T468: 5.15
A469: 468 | B469: 38359 | C469: 1545630.1 | D469: =C469/E469 -> 35328.688 | E469: 43.75 | F469: =(D469/100000) -> 0.35328688 | G469: =(F469/'Yearly GDP'!$B$4)*100 -> 49.818357 | H469: =(K469/I469) -> 0.9717232 | I469: =(J469/L469)*100 -> 6.7385445 | J469: =L469/O469 -> 135.81536 | K469: 6.548 | L469: 2015.5 | M469: 3.49 | N469: =K469-I469 -> -0.19054447 | O469: 14.84 | P469: 4.275 | Q469: =K469-P469 -> 2.273 | R469: 83.72 | S469: =(O469*T469) -> 76.426 | T469: 5.15
A470: 469 | B470: 38362 | C470: 1530226.9 | D470: =C470/E470 -> 34865.047 | E470: 43.89 | F470: =(D470/100000) -> 0.34865047 | G470: =(F470/'Yearly GDP'!$B$4)*100 -> 49.164559 | H470: =(K470/I470) -> 0.9605304 | I470: =(J470/L470)*100 -> 6.8587106 | J470: =L470/O470 -> 135.93964 | K470: 6.588 | L470: 1982 | M470: 3.44 | N470: =K470-I470 -> -0.27071056 | O470: 14.58 | P470: 4.273 | Q470: =K470-P470 -> 2.315 | R470: 83.36 | S470: =(O470*T470) -> 75.816 | T470: 5.2
A471: 470 | B471: 38363 | C471: 1502001 | D471: =C471/E471 -> 34351.081 | E471: 43.725 | F471: =(D471/100000) -> 0.34351081 | G471: =(F471/'Yearly GDP'!$B$4)*100 -> 48.439795 | H471: =(K471/I471) -> 0.9418098 | I471: =(J471/L471)*100 -> 6.9589422 | J471: =L471/O471 -> 135.84203 | K471: 6.554 | L471: 1952.05 | M471: 3.39 | N471: =K471-I471 -> -0.40494224 | O471: 14.37 | P471: 4.244 | Q471: =K471-P471 -> 2.31 | R471: 83.07 | S471: =(O471*T471) -> 79.035 | T471: 5.5
A472: 471 | B472: 38364 | C472: 1462287 | D472: =C472/E472 -> 33569.49 | E472: 43.56 | F472: =(D472/100000) -> 0.3356949 | G472: =(F472/'Yearly GDP'!$B$4)*100 -> 47.337644 | H472: =(K472/I472) -> 0.9246305 | I472: =(J472/L472)*100 -> 7.1174377 | J472: =L472/O472 -> 136.19929 | K472: 6.581 | L472: 1913.6 | M472: 3.32 | N472: =K472-I472 -> -0.53643772 | O472: 14.05 | P472: 4.238 | Q472: =K472-P472 -> 2.343 | R472: 82.18 | S472: =(O472*T472) -> 74.465 | T472: 5.3
A473: 472 | B473: 38365 | C473: 1497439 | D473: =C473/E473 -> 34419.929 | E473: 43.505 | F473: =(D473/100000) -> 0.34419929 | G473: =(F473/'Yearly GDP'!$B$4)*100 -> 48.53688 | H473: =(K473/I473) -> 0.942221 | I473: =(J473/L473)*100 -> 6.9686411 | J473: =L473/O473 -> 136.20557 | K473: 6.566 | L473: 1954.55 | M473: 3.39 | N473: =K473-I473 -> -0.40264111 | O473: 14.35 | P473: 4.167 | Q473: =K473-P473 -> 2.399 | R473: 82.57 | S473: =(O473*T473) -> 75.6245 | T473: 5.27
A474: 473 | B474: 38366 | C474: 1483272.2 | D474: =C474/E474 -> 34016.104 | E474: 43.605 | F474: =(D474/100000) -> 0.34016104 | G474: =(F474/'Yearly GDP'!$B$4)*100 -> 47.967431 | H474: =(K474/I474) -> 0.9426864 | I474: =(J474/L474)*100 -> 7.0521862 | J474: =L474/O474 -> 136.18477 | K474: 6.648 | L474: 1931.1 | M474: 3.35 | N474: =K474-I474 -> -0.40418618 | O474: 14.18 | P474: 4.22 | Q474: =K474-P474 -> 2.428 | R474: 83.13 | S474: =(O474*T474) -> 74.7286 | T474: 5.27
A475: 474 | B475: 38369 | C475: 1479794.1 | D475: =C475/E475 -> 33940.232 | E475: 43.6 | F475: =(D475/100000) -> 0.33940232 | G475: =(F475/'Yearly GDP'!$B$4)*100 -> 47.860441 | H475: =(K475/I475) -> 0.947973 | I475: =(J475/L475)*100 -> 7.057163 | J475: =L475/O475 -> 136.4079 | K475: 6.69 | L475: 1932.9 | M475: 3.35 | N475: =K475-I475 -> -0.36716302 | O475: 14.17 | P475: 4.22 | Q475: =K475-P475 -> 2.47 | R475: 83.13 | S475: =(O475*T475) -> 75.101 | T475: 5.3
A476: 475 | B476: 38370 | C476: 1483489 | D476: =C476/E476 -> 33954.887 | E476: 43.69 | F476: =(D476/100000) -> 0.33954887 | G476: =(F476/'Yearly GDP'!$B$4)*100 -> 47.881107 | H476: =(K476/I476) -> 0.9531423 | I476: =(J476/L476)*100 -> 7.0472163 | J476: =L476/O476 -> 136.29669 | K476: 6.717 | L476: 1934.05 | M476: 3.36 | N476: =K476-I476 -> -0.33021635 | O476: 14.19 | P476: 4.193 | Q476: =K476-P476 -> 2.524 | R476: 83.46 | S476: =(O476*T476) -> 73.788 | T476: 5.2
... A525: 524 | B525: 38442 | C525: 1585585 | D525: =C525/E525 -> 36304.179 | E525: 43.675 | F525: =(D525/100000) -> 0.36304179 | G525: =(F525/'Yearly GDP'!$B$4)*100 -> 51.193934 | H525: =(K525/I525) -> 0.974696 | I525: =(J525/L525)*100 -> 6.8493151 | J525: =L525/O525 -> 139.42808 | K525: 6.676 | L525: 2035.65 | M525: 3.82 | N525: =K525-I525 -> -0.17331507 | O525: 14.6 | P525: 4.488 | Q525: =K525-P525 -> 2.188 | R525: 84.05 | S525: =(O525*T525) -> 76.65 | T525: 5.25
...

Sheet Buffett indicator
A1: Country Name | B1: India
A2: Country Code | B2: IND
A3: Indicator Name | B3: Market capitalization of listed domestic companies (% of GDP)
A4: Indicator Code | B4: Market cap to GDP
A5: 1960
A6: 1961
A7: 1962
A8: 1963
A9: 1964
A10: 1965
A11: 1966
A12: 1967
A13: 1968
A14: 1969
A15: 1970
A16: 1971
... A44: 1999
A45: 2000 | B45: 48.17475
A46: 2001 | B46: 30.646752
A47: 2002 | B47: 33.438061
A48: 2003 | B48: 50.846571
A49: 2004 | B49: 58.597294
A50: 2005 | B50: 76.152115
A51: 2006 | B51: 95.215152
A52: 2007 | B52: 161.23945
A53: 2008 | B53: 66.003104
A54: 2009 | B54: 101.89449
A55: 2010 | B55: 105.18295
A56: 2011 | B56: 68.270064
... A70: 2025 | B70: 137.7

Sheet Future return
B1: Year | C1: Nifty | D1: Nifty aft 5yr | E1: Future 5yr CAGR | I1: Valuation Bucket
B2: 2000 | C2: 1263.55 | D2: 2836.55 | E2: =(D2/C2)^(1/5)-1 -> 0.17554593 | I2: Score | J2: Bucket
B3: 2001 | C3: 1059.05 | D3: 3966.4 | E3: =(D3/C3)^(1/5)-1 -> 0.30225493 | I3: 0-20% | J3: Deep Value
B4: 2002 | C4: 1093.5 | D4: 6138.6 | E4: =(D4/C4)^(1/5)-1 -> 0.41205011 | I4: 20-40% | J4: Cheap
B5: 2003 | C5: 1879.75 | D5: 2959.15 | E5: =(D5/C5)^(1/5)-1 -> 0.09499813 | I5: 40-60% | J5: Fair
B6: 2004 | C6: 2080.5 | D6: 5201.05 | E6: =(D6/C6)^(1/5)-1 -> 0.2011152 | I6: 60-80% | J6: Expensive
B7: 2005 | C7: 2836.55 | D7: 6134.5 | E7: =(D7/C7)^(1/5)-1 -> 0.16680356 | I7: 80-100% | J7: Very Expensive
B8: 2006 | C8: 3966.4 | D8: 4624.3 | E8: =(D8/C8)^(1/5)-1 -> 0.031169119
B9: 2007 | C9: 6138.6 | D9: 5905.1 | E9: =(D9/C9)^(1/5)-1 -> -0.0077260631
B10: 2008 | C10: 2959.15 | D10: 6304 | E10: =(D10/C10)^(1/5)-1 -> 0.16329496
B11: 2009 | C11: 5201.05 | D11: 8282.7 | E11: =(D11/C11)^(1/5)-1 -> 0.097529445
B12: 2010 | C12: 6134.5 | D12: 7964.35 | E12: =(D12/C12)^(1/5)-1 -> 0.053596291
B13: 2011 | C13: 4624.3 | D13: 8185.8 | E13: =(D13/C13)^(1/5)-1 -> 0.12099332
B14: 2012 | C14: 5905.1 | D14: 10530.7 | E14: =(D14/C14)^(1/5)-1 -> 0.12265418
B15: 2013 | C15: 6304 | D15: 10862.55 | E15: =(D15/C15)^(1/5)-1 -> 0.11496983
B16: 2014 | C16: 8282.7 | D16: 12168.45 | E16: =(D16/C16)^(1/5)-1 -> 0.079972423
B17: 2015 | C17: 7964.35 | D17: 13981.75 | E17: =(D17/C17)^(1/5)-1 -> 0.11913438
B18: 2016 | C18: 8185.8 | D18: 17354.05 | E18: =(D18/C18)^(1/5)-1 -> 0.1621654
B19: 2017 | C19: 10530.7 | D19: 18105.3 | E19: =(D19/C19)^(1/5)-1 -> 0.11447337
... B22: 2020 | C22: 13981.75 | D22: 26129.6 | E22: =(D22/C22)^(1/5)-1 -> 0.13322004
B23: 2021 | C23: 17354.05
B24: 2022 | C24: 18105.3
B25: 2023 | C25: 21731.4
B26: 2024 | C26: 23644.8
B27: 2025 | C27: 26129.6

Sheet Yearly GDP
A1: Year | B1: (USD) in Trillions | C1: GDP | D1: CY changes
A2: 2002 | B2: =C2/1000 -> 0.51494 | C2: 514.94
A3: 2003 | B3: 0.6077 | C3: =B3*1000 -> 607.7 | D3: =(C3-C2)/C2 -> 0.18013749
A4: 2004 | B4: 0.70915 | C4: =B4*1000 -> 709.15 | D4: =(C4-C3)/C3 -> 0.16694092
A5: 2005 | B5: 0.82038 | C5: =B5*1000 -> 820.38 | D5: =(C5-C4)/C4 -> 0.15684975
A6: 2006 | B6: 0.94026 | C6: =B6*1000 -> 940.26 | D6: =(C6-C5)/C5 -> 0.1461274
A7: 2007 | B7: 1.22 | C7: =B7*1000 -> 1220 | D7: =(C7-C6)/C6 -> 0.29751345
A8: 2008 | B8: 1.2 | C8: =B8*1000 -> 1200 | D8: =(C8-C7)/C7 -> -0.016393443
A9: 2009 | B9: 1.34 | C9: =B9*1000 -> 1340 | D9: =(C9-C8)/C8 -> 0.11666667
A10: 2010 | B10: 1.68 | C10: =B10*1000 -> 1680 | D10: =(C10-C9)/C9 -> 0.25373134
A11: 2011 | B11: 1.82 | C11: =B11*1000 -> 1820 | D11: =(C11-C10)/C10 -> 0.083333333
A12: 2012 | B12: 1.83 | C12: =B12*1000 -> 1830 | D12: =(C12-C11)/C11 -> 0.0054945055
A13: 2013 | B13: 1.86 | C13: =B13*1000 -> 1860 | D13: =(C13-C12)/C12 -> 0.016393443
A14: 2014 | B14: 2.04 | C14: =B14*1000 -> 2040 | D14: =(C14-C13)/C13 -> 0.096774194
... A24: 2024 | B24: 3.68 | C24: =B24*1000 -> 3680 | D24: =(C24-C23)/C23 -> 0.030812325
A25: 2025

Sheet PE PB
A1: Date | B1: P/E | C1: P/B
A2: 36889 | B2: 19.2 | C2: 4.14
A3: 36888 | B3: 18.98 | C3: 4.09
A4: 36887 | B4: 18.67 | C4: 4.02
A5: 36886 | B5: 18.42 | C5: 3.97
A6: 36882 | B6: 18.87 | C6: 4.07
A7: 36881 | B7: 19.41 | C7: 4.18
A8: 36880 | B8: 19.68 | C8: 4.24
A9: 36879 | B9: 19.88 | C9: 4.28
A10: 36878 | B10: 19.98 | C10: 4.31
A11: 36875 | B11: 19.91 | C11: 4.29
A12: 36874 | B12: 20.47 | C12: 4.41
A13: 36873 | B13: 20.54 | C13: 4.43
... A6467: 45658 | B6467: 21.88 | C6467: 3.54
